Workbook
Name v_cis_1: 'Pull Db Dbeaver '!#REF!
Name v_cis_datafile: 'Pull Data File'!#REF!
Name v_cis_datafile_1: 'Pull Data File'!$A$1:$DK$30
Name v_cis_db: 'Pull Data File'!#REF!
Name v_cis_db_1: 'Pull Db Dbeaver '!#REF!
Name v_cis_db_2: 'Pull Db Dbeaver '!#REF!
Name v_cis_db_3: 'Pull Db Dbeaver '!#REF!
Name v_cis_db_4: 'Pull Db Dbeaver '!$A$1:$DK$30

Sheet Summary
A2: Case 1 : The count of records refers to the number of records that match between querying a table and a file, including both data and control files.
A3: Case 2: Ensure that the number of columns matches with the CBR.
A4: Case 3 :Data type: string. For instance, in cases where a long decimal is pulled out as text, additional handling and formatting are required.
A5: Case 4 :Data correctness: Ensure that the data extracted from the file matches the data in the table.
A7: Table
A8: dgtl_fctrng_v_cis
A11: Case 1 | B11: Case2 | C11: Case3 | D11: Case4
A12: ='Extraction Unit Test Case1 '!A8 -> PASSED | B12: ='Extraction Unit Test Case 2'!A8 -> PASSED | C12: ='Extraction Unit Test Case3'!A8 -> PASSED | D12: ='Extraction Unit Test Case4'!A8 -> FAILED

Sheet Extraction Unit Test Case1 
A1: Case 1 : The count of records refers to the number of records that match between querying a table and a file, including both data and control files.
A3: Table
A4: dgtl_fctrng_v_cis
A7: STATUS
A8: =IF(A13=B13, "PASSED", "FAILED") -> PASSED
A10: POS_DT | B10: 45420
A12: Record Count In File | B12: Record Count In Database | E12: Reference
A13: 8127 | B13: 8127 | F13: CTL File
F25: Database

Sheet Extraction Unit Test Case 2
A1: Case 2: Ensure that the number of columns matches with the CBR.
A3: Table
A4: dgtl_fctrng_v_cis
A7: STATUS
A8: =IF(F34=H34, "PASSED", "FAILED") -> PASSED
A10: SELECT orgcode, cisno, nameth, nameen, thtitle, thfirstname, thsurname, thmiddlename, entitle, enfirstname, ensurname, enmiddlename, riskrate, doctype, docno, docissuedate, docexpiredate, ciscusttype, ciscustname, cisbiztype, cisbizname, bizdesc, regid, rmname, rmmobile, rmemail, psname, psmobile, psemail, legalplacename, legalboxno, legalhouseno, legalvillageno, legalvillage, legalbuildingname, legalroomno, legalfloorno, legalalley, legalstreetname, legaltamboldesc, legalamphurdesc, legalprovincedesc, legalpostal, legalcountry, legaladdr1, legaladdr2, mailingplacename, mailingboxno, mailinghouseno, mailingvillageno, mailingvillage, mailingbuildingname, mailingroomno, mailingfloorno, mailingalley, mailingstreetname, mailingtamboldesc, mailingamphurdesc, mailingprovincedesc, mailingpostal, mailingcountry, mailingaddr1, mailingaddr2, officeplacename, officeboxno, officehouseno, officevillageno, officevillage, officebuildingname, officeroomno, officefloorno, officealley, officestreetname, officetamboldesc, officeamphurdesc, officeprovincedesc, officepostal, officecountry, officeaddr1, officeaddr2, tel, telext, fax, mobilephone, email, website, nationality, comptype, holidaycode, contactperson, contactmobile, contacttel, contacttelext, contactemail, contactfax, contactremarks, updateby, updatedate, updatetime, version, residence, createby, createdate, createtime, colplanningrem, maxsublm, docremarks, custsegment, birthdate, custtypecode, prospectflag, docgovtissue, kbankid, branch, rmid FROM V_CIS
A33: No. | B33: Field From Query | C33: Field From CBR | D33: Match | F33: Columns Field from query | H33: Columns Field from CBR
A34: 1 | B34: OrgCode | C34: orgcode | D34: =B34=C34 -> TRUE | F34: 115 | H34: 115
A35: 2 | B35: CisNo | C35: cisno | D35: =B35=C35 -> TRUE
A36: 3 | B36: NameTh | C36: nameth | D36: =B36=C36 -> TRUE
A37: 4 | B37: NameEn | C37: nameen | D37: =B37=C37 -> TRUE
A38: 5 | B38: ThTitle | C38: thtitle | D38: =B38=C38 -> TRUE
A39: 6 | B39: ThFirstName | C39: thfirstname | D39: =B39=C39 -> TRUE
A40: 7 | B40: ThSurName | C40: thsurname | D40: =B40=C40 -> TRUE
A41: 8 | B41: ThMiddleName | C41: thmiddlename | D41: =B41=C41 -> TRUE
A42: 9 | B42: EnTitle | C42: entitle | D42: =B42=C42 -> TRUE
A43: 10 | B43: EnFirstName | C43: enfirstname | D43: =B43=C43 -> TRUE
A44: 11 | B44: EnSurName | C44: ensurname | D44: =B44=C44 -> TRUE
A45: 12 | B45: EnMiddleName | C45: enmiddlename | D45: =B45=C45 -> TRUE
A46: 13 | B46: RiskRate | C46: riskrate | D46: =B46=C46 -> TRUE
... A148: 115 | B148: RmID | C148: rmid | D148: =B148=C148 -> TRUE

Sheet Extraction Unit Test Case3
A1: Case 3 :Data type: string. For instance, in cases where a long decimal is pulled out as text, additional handling and formatting are required.
A3: Table
A4: dgtl_fctrng_v_cis
A7: STATUS
A8: =IF(COUNTIF(F38:F152, TRUE) = COUNTA(F38:F152), "PASSED", "FAILED") -> PASSED
A37: Field | B37: Value | C37: Data Type | D37: Data Size | E37: Date Format | F37: Match
A38: OrgCode | B38: "KBANK" | C38: varchar | D38: 25
A39: CisNo | B39: "0000000005" | C39: varchar | D39: 10
A40: NameTh | B40: "บจก. ณรกฤต" | C40: varchar | D40: 200
A41: NameEn | B41: "NARAKRIT CO.,LTD." | C41: varchar | D41: 200
A42: ThTitle | B42: "บจก." | C42: varchar | D42: 20
A43: ThFirstName | B43: "ณรกฤต" | C43: varchar | D43: 120
A44: ThSurName | B44: "" | C44: varchar | D44: 50
A45: ThMiddleName | B45: "" | C45: varchar | D45: 60
A46: EnTitle | B46: "CO.,LTD." | C46: varchar | D46: 20
A47: EnFirstName | B47: "NARAKRIT" | C47: varchar | D47: 120
A48: EnSurName | B48: "" | C48: varchar | D48: 50
A49: EnMiddleName | B49: "" | C49: varchar | D49: 60
... A136: UpdateTime | B136: "09:50:32 " | C136: char | D136: 10
A137: Version | B137: "5" | C137: int
A138: Residence | B138: "Y" | C138: char | D138: 1
A139: CreateBy | B139: "KB000000" | C139: varchar | D139: 50
A140: CreateDate | B140: "2020-02-15" | C140: char | D140: 10
A141: CreateTime | B141: "05:16:03" | C141: varchar | D141: 10
A142: ColPlanningRem | B142: "DUEตามนัด" | C142: varchar | D142: 500
A143: MaxSubLM | B143: "0.00" | C143: numeric | D143: 18,2 | F143: TRUE
A144: DocRemarks | B144: "" | C144: varchar | D144: 200
A145: CustSegment | B145: "UM" | C145: varchar | D145: 50
A146: BirthDate | B146: "1943-02-05" | C146: varchar | D146: 10
A147: CustTypeCode | B147: "O" | C147: varchar | D147: 5
A148: ProspectFlag | B148: "C" | C148: varchar | D148: 5
A149: DocGovtIssue | B149: "" | C149: varchar | D149: 30
A150: KBankID | B150: "0000138286" | C150: varchar | D150: 10
A151: Branch | B151: "สำนักงานใหญ่" | C151: varchar | D151: 50
A152: RmID | B152: "440759" | C152: varchar | D152: 11

Sheet Extraction Unit Test Case4
A1: Case 4 :Data correctness: Ensure that the data extracted from the file matches the data in the table.
A3: Table
A4: dgtl_fctrng_v_cis
A7: STATUS
A8: =IF(COUNTIF(B11:B40, TRUE) = COUNTA(B11:B40), "PASSED", "FAILED") -> FAILED
A11: 1 | B11: {=IF(AND(C1:DM1=TRUE), TRUE, FALSE)} -> FALSE | C11: {='Pull Db Dbeaver '!A1:DK1='Pull Data File'!A1:DK1} -> TRUE | D11: TRUE | E11: TRUE | F11: TRUE | G11: TRUE | H11: TRUE | I11: TRUE | J11: TRUE | K11: TRUE | L11: TRUE | M11: TRUE | N11: TRUE | O11: TRUE | P11: TRUE | Q11: TRUE | R11: TRUE | S11: TRUE | T11: TRUE | U11: TRUE | V11: TRUE | W11: TRUE | X11: TRUE | Y11: TRUE | Z11: TRUE | AA11: TRUE | AB11: TRUE | AC11: FALSE | AD11: FALSE | AE11: FALSE | AF11: TRUE | AG11: TRUE | AH11: TRUE | AI11: TRUE | AJ11: TRUE | AK11: TRUE | AL11: TRUE | AM11: TRUE | AN11: TRUE | AO11: TRUE | AP11: TRUE | AQ11: TRUE | AR11: TRUE | AS11: TRUE | AT11: TRUE | AU11: TRUE | AV11: TRUE | AW11: TRUE | AX11: TRUE | AY11: TRUE | AZ11: TRUE | BA11: TRUE | BB11: TRUE | BC11: TRUE | BD11: TRUE | BE11: TRUE | BF11: TRUE | BG11: TRUE | BH11: TRUE | BI11: TRUE | BJ11: TRUE | BK11: TRUE | BL11: TRUE | BM11: TRUE | BN11: TRUE | BO11: TRUE | BP11: TRUE | BQ11: TRUE | BR11: TRUE | BS11: TRUE | BT11: TRUE | BU11: TRUE | BV11: TRUE | BW11: TRUE | BX11: TRUE | BY11: TRUE | BZ11: TRUE | CA11: TRUE | CB11: TRUE | CC11: TRUE | CD11: TRUE | CE11: TRUE | CF11: TRUE | CG11: TRUE | CH11: TRUE | CI11: TRUE | CJ11: TRUE | CK11: TRUE | CL11: TRUE | CM11: TRUE | CN11: FALSE | CO11: FALSE | CP11: FALSE | CQ11: FALSE | CR11: FALSE | CS11: FALSE | CT11: TRUE | CU11: TRUE | CV11: TRUE | CW11: TRUE | CX11: TRUE | CY11: TRUE | CZ11: TRUE | DA11: TRUE | DB11: TRUE | DC11: TRUE | DD11: TRUE | DE11: TRUE | DF11: TRUE | DG11: TRUE | DH11: TRUE | DI11: TRUE | DJ11: TRUE | DK11: TRUE | DL11: TRUE | DM11: TRUE
A12: 2 | B12: {=IF(AND(C2:DM2=TRUE), TRUE, FALSE)} -> FALSE | C12: {='Pull Db Dbeaver '!A2:DK2='Pull Data File'!A2:DK2} -> TRUE | D12: TRUE | E12: TRUE | F12: TRUE | G12: TRUE | H12: TRUE | I12: TRUE | J12: TRUE | K12: TRUE | L12: TRUE | M12: TRUE | N12: TRUE | O12: TRUE | P12: TRUE | Q12: TRUE | R12: TRUE | S12: TRUE | T12: TRUE | U12: TRUE | V12: TRUE | W12: TRUE | X12: TRUE | Y12: TRUE | Z12: TRUE | AA12: TRUE | AB12: TRUE | AC12: FALSE | AD12: FALSE | AE12: FALSE | AF12: TRUE | AG12: TRUE | AH12: TRUE | AI12: TRUE | AJ12: TRUE | AK12: TRUE | AL12: TRUE | AM12: TRUE | AN12: TRUE | AO12: TRUE | AP12: TRUE | AQ12: TRUE | AR12: TRUE | AS12: TRUE | AT12: TRUE | AU12: TRUE | AV12: TRUE | AW12: TRUE | AX12: TRUE | AY12: TRUE | AZ12: TRUE | BA12: TRUE | BB12: TRUE | BC12: TRUE | BD12: TRUE | BE12: TRUE | BF12: TRUE | BG12: TRUE | BH12: TRUE | BI12: TRUE | BJ12: TRUE | BK12: TRUE | BL12: TRUE | BM12: TRUE | BN12: TRUE | BO12: TRUE | BP12: TRUE | BQ12: TRUE | BR12: TRUE | BS12: TRUE | BT12: TRUE | BU12: TRUE | BV12: TRUE | BW12: TRUE | BX12: TRUE | BY12: TRUE | BZ12: TRUE | CA12: TRUE | CB12: TRUE | CC12: TRUE | CD12: TRUE | CE12: TRUE | CF12: TRUE | CG12: TRUE | CH12: TRUE | CI12: TRUE | CJ12: FALSE | CK12: TRUE | CL12: TRUE | CM12: TRUE | CN12: FALSE | CO12: FALSE | CP12: FALSE | CQ12: FALSE | CR12: FALSE | CS12: FALSE | CT12: TRUE | CU12: TRUE | CV12: TRUE | CW12: TRUE | CX12: TRUE | CY12: TRUE | CZ12: TRUE | DA12: TRUE | DB12: TRUE | DC12: TRUE | DD12: TRUE | DE12: TRUE | DF12: TRUE | DG12: TRUE | DH12: TRUE | DI12: TRUE | DJ12: TRUE | DK12: TRUE | DL12: TRUE | DM12: TRUE
A13: 3 | B13: {=IF(AND(C3:DM3=TRUE), TRUE, FALSE)} -> FALSE | C13: {='Pull Db Dbeaver '!A3:DK3='Pull Data File'!A3:DK3} -> TRUE | D13: TRUE | E13: TRUE | F13: TRUE | G13: TRUE | H13: TRUE | I13: TRUE | J13: TRUE | K13: TRUE | L13: TRUE | M13: TRUE | N13: TRUE | O13: TRUE | P13: TRUE | Q13: TRUE | R13: TRUE | S13: TRUE | T13: TRUE | U13: TRUE | V13: TRUE | W13: TRUE | X13: TRUE | Y13: TRUE | Z13: TRUE | AA13: TRUE | AB13: TRUE | AC13: FALSE | AD13: FALSE | AE13: FALSE | AF13: TRUE | AG13: TRUE | AH13: TRUE | AI13: TRUE | AJ13: TRUE | AK13: TRUE | AL13: TRUE | AM13: TRUE | AN13: TRUE | AO13: TRUE | AP13: TRUE | AQ13: TRUE | AR13: TRUE | AS13: TRUE | AT13: TRUE | AU13: TRUE | AV13: TRUE | AW13: TRUE | AX13: TRUE | AY13: TRUE | AZ13: TRUE | BA13: TRUE | BB13: TRUE | BC13: TRUE | BD13: TRUE | BE13: TRUE | BF13: TRUE | BG13: TRUE | BH13: TRUE | BI13: TRUE | BJ13: TRUE | BK13: TRUE | BL13: TRUE | BM13: TRUE | BN13: TRUE | BO13: TRUE | BP13: TRUE | BQ13: TRUE | BR13: TRUE | BS13: TRUE | BT13: TRUE | BU13: TRUE | BV13: TRUE | BW13: TRUE | BX13: TRUE | BY13: TRUE | BZ13: TRUE | CA13: TRUE | CB13: TRUE | CC13: TRUE | CD13: TRUE | CE13: TRUE | CF13: TRUE | CG13: TRUE | CH13: TRUE | CI13: TRUE | CJ13: FALSE | CK13: TRUE | CL13: TRUE | CM13: TRUE | CN13: FALSE | CO13: FALSE | CP13: FALSE | CQ13: FALSE | CR13: FALSE | CS13: FALSE | CT13: TRUE | CU13: TRUE | CV13: TRUE | CW13: TRUE | CX13: TRUE | CY13: TRUE | CZ13: TRUE | DA13: TRUE | DB13: TRUE | DC13: TRUE | DD13: TRUE | DE13: TRUE | DF13: TRUE | DG13: TRUE | DH13: TRUE | DI13: TRUE | DJ13: TRUE | DK13: TRUE | DL13: TRUE | DM13: TRUE
A14: 4 | B14: {=IF(AND(C4:DM4=TRUE), TRUE, FALSE)} -> FALSE | C14: {='Pull Db Dbeaver '!A4:DK4='Pull Data File'!A4:DK4} -> TRUE | D14: TRUE | E14: TRUE | F14: TRUE | G14: TRUE | H14: TRUE | I14: TRUE | J14: TRUE | K14: TRUE | L14: TRUE | M14: TRUE | N14: TRUE | O14: TRUE | P14: TRUE | Q14: TRUE | R14: TRUE | S14: TRUE | T14: TRUE | U14: TRUE | V14: TRUE | W14: TRUE | X14: TRUE | Y14: TRUE | Z14: TRUE | AA14: TRUE | AB14: TRUE | AC14: FALSE | AD14: FALSE | AE14: FALSE | AF14: TRUE | AG14: TRUE | AH14: TRUE | AI14: TRUE | AJ14: TRUE | AK14: TRUE | AL14: TRUE | AM14: TRUE | AN14: TRUE | AO14: TRUE | AP14: TRUE | AQ14: TRUE | AR14: TRUE | AS14: TRUE | AT14: TRUE | AU14: TRUE | AV14: TRUE | AW14: TRUE | AX14: TRUE | AY14: TRUE | AZ14: TRUE | BA14: TRUE | BB14: TRUE | BC14: TRUE | BD14: TRUE | BE14: TRUE | BF14: TRUE | BG14: TRUE | BH14: TRUE | BI14: TRUE | BJ14: TRUE | BK14: TRUE | BL14: TRUE | BM14: TRUE | BN14: TRUE | BO14: TRUE | BP14: TRUE | BQ14: TRUE | BR14: TRUE | BS14: TRUE | BT14: TRUE | BU14: TRUE | BV14: TRUE | BW14: TRUE | BX14: TRUE | BY14: TRUE | BZ14: TRUE | CA14: TRUE | CB14: TRUE | CC14: TRUE | CD14: TRUE | CE14: TRUE | CF14: TRUE | CG14: TRUE | CH14: TRUE | CI14: TRUE | CJ14: FALSE | CK14: TRUE | CL14: TRUE | CM14: TRUE | CN14: FALSE | CO14: FALSE | CP14: FALSE | CQ14: FALSE | CR14: FALSE | CS14: FALSE | CT14: TRUE | CU14: TRUE | CV14: TRUE | CW14: TRUE | CX14: TRUE | CY14: TRUE | CZ14: TRUE | DA14: TRUE | DB14: TRUE | DC14: TRUE | DD14: TRUE | DE14: TRUE | DF14: TRUE | DG14: TRUE | DH14: TRUE | DI14: TRUE | DJ14: TRUE | DK14: TRUE | DL14: TRUE | DM14: TRUE
A15: 5 | B15: {=IF(AND(C5:DM5=TRUE), TRUE, FALSE)} -> FALSE | C15: {='Pull Db Dbeaver '!A5:DK5='Pull Data File'!A5:DK5} -> TRUE | D15: TRUE | E15: TRUE | F15: TRUE | G15: TRUE | H15: TRUE | I15: TRUE | J15: TRUE | K15: TRUE | L15: TRUE | M15: TRUE | N15: TRUE | O15: TRUE | P15: TRUE | Q15: TRUE | R15: TRUE | S15: TRUE | T15: TRUE | U15: TRUE | V15: TRUE | W15: TRUE | X15: TRUE | Y15: TRUE | Z15: TRUE | AA15: TRUE | AB15: TRUE | AC15: FALSE | AD15: FALSE | AE15: FALSE | AF15: TRUE | AG15: TRUE | AH15: TRUE | AI15: TRUE | AJ15: TRUE | AK15: TRUE | AL15: TRUE | AM15: TRUE | AN15: TRUE | AO15: TRUE | AP15: TRUE | AQ15: TRUE | AR15: TRUE | AS15: TRUE | AT15: TRUE | AU15: TRUE | AV15: TRUE | AW15: TRUE | AX15: TRUE | AY15: TRUE | AZ15: TRUE | BA15: TRUE | BB15: TRUE | BC15: TRUE | BD15: TRUE | BE15: TRUE | BF15: TRUE | BG15: TRUE | BH15: TRUE | BI15: TRUE | BJ15: TRUE | BK15: TRUE | BL15: TRUE | BM15: TRUE | BN15: TRUE | BO15: TRUE | BP15: TRUE | BQ15: TRUE | BR15: TRUE | BS15: TRUE | BT15: TRUE | BU15: TRUE | BV15: TRUE | BW15: TRUE | BX15: TRUE | BY15: TRUE | BZ15: TRUE | CA15: TRUE | CB15: TRUE | CC15: TRUE | CD15: TRUE | CE15: TRUE | CF15: TRUE | CG15: TRUE | CH15: TRUE | CI15: TRUE | CJ15: FALSE | CK15: TRUE | CL15: TRUE | CM15: TRUE | CN15: FALSE | CO15: FALSE | CP15: FALSE | CQ15: FALSE | CR15: FALSE | CS15: FALSE | CT15: TRUE | CU15: TRUE | CV15: TRUE | CW15: TRUE | CX15: TRUE | CY15: TRUE | CZ15: TRUE | DA15: TRUE | DB15: TRUE | DC15: TRUE | DD15: TRUE | DE15: TRUE | DF15: TRUE | DG15: TRUE | DH15: TRUE | DI15: TRUE | DJ15: TRUE | DK15: TRUE | DL15: TRUE | DM15: TRUE
A16: 6 | B16: {=IF(AND(C6:DM6=TRUE), TRUE, FALSE)} -> FALSE | C16: {='Pull Db Dbeaver '!A6:DK6='Pull Data File'!A6:DK6} -> TRUE | D16: TRUE | E16: TRUE | F16: TRUE | G16: TRUE | H16: TRUE | I16: TRUE | J16: TRUE | K16: TRUE | L16: TRUE | M16: TRUE | N16: TRUE | O16: TRUE | P16: TRUE | Q16: TRUE | R16: TRUE | S16: TRUE | T16: TRUE | U16: TRUE | V16: TRUE | W16: TRUE | X16: TRUE | Y16: TRUE | Z16: TRUE | AA16: TRUE | AB16: TRUE | AC16: FALSE | AD16: FALSE | AE16: FALSE | AF16: TRUE | AG16: TRUE | AH16: TRUE | AI16: TRUE | AJ16: TRUE | AK16: TRUE | AL16: TRUE | AM16: TRUE | AN16: TRUE | AO16: TRUE | AP16: TRUE | AQ16: TRUE | AR16: TRUE | AS16: TRUE | AT16: TRUE | AU16: TRUE | AV16: TRUE | AW16: TRUE | AX16: TRUE | AY16: TRUE | AZ16: TRUE | BA16: TRUE | BB16: TRUE | BC16: TRUE | BD16: TRUE | BE16: TRUE | BF16: TRUE | BG16: TRUE | BH16: TRUE | BI16: TRUE | BJ16: TRUE | BK16: TRUE | BL16: TRUE | BM16: TRUE | BN16: TRUE | BO16: TRUE | BP16: TRUE | BQ16: TRUE | BR16: TRUE | BS16: TRUE | BT16: TRUE | BU16: TRUE | BV16: TRUE | BW16: TRUE | BX16: TRUE | BY16: TRUE | BZ16: TRUE | CA16: TRUE | CB16: TRUE | CC16: TRUE | CD16: TRUE | CE16: TRUE | CF16: TRUE | CG16: TRUE | CH16: TRUE | CI16: TRUE | CJ16: FALSE | CK16: TRUE | CL16: TRUE | CM16: TRUE | CN16: FALSE | CO16: FALSE | CP16: FALSE | CQ16: FALSE | CR16: FALSE | CS16: FALSE | CT16: TRUE | CU16: TRUE | CV16: TRUE | CW16: TRUE | CX16: TRUE | CY16: TRUE | CZ16: TRUE | DA16: TRUE | DB16: TRUE | DC16: TRUE | DD16: TRUE | DE16: TRUE | DF16: TRUE | DG16: TRUE | DH16: TRUE | DI16: TRUE | DJ16: TRUE | DK16: TRUE | DL16: TRUE | DM16: TRUE
A17: 7 | B17: {=IF(AND(C7:DM7=TRUE), TRUE, FALSE)} -> FALSE | C17: {='Pull Db Dbeaver '!A7:DK7='Pull Data File'!A7:DK7} -> TRUE | D17: TRUE | E17: TRUE | F17: TRUE | G17: TRUE | H17: TRUE | I17: TRUE | J17: TRUE | K17: TRUE | L17: TRUE | M17: TRUE | N17: TRUE | O17: TRUE | P17: TRUE | Q17: TRUE | R17: TRUE | S17: TRUE | T17: TRUE | U17: TRUE | V17: TRUE | W17: TRUE | X17: TRUE | Y17: TRUE | Z17: TRUE | AA17: TRUE | AB17: TRUE | AC17: FALSE | AD17: FALSE | AE17: FALSE | AF17: TRUE | AG17: TRUE | AH17: TRUE | AI17: TRUE | AJ17: TRUE | AK17: TRUE | AL17: TRUE | AM17: TRUE | AN17: TRUE | AO17: TRUE | AP17: TRUE | AQ17: TRUE | AR17: TRUE | AS17: TRUE | AT17: TRUE | AU17: TRUE | AV17: TRUE | AW17: TRUE | AX17: TRUE | AY17: TRUE | AZ17: TRUE | BA17: TRUE | BB17: TRUE | BC17: TRUE | BD17: TRUE | BE17: TRUE | BF17: TRUE | BG17: TRUE | BH17: TRUE | BI17: TRUE | BJ17: TRUE | BK17: TRUE | BL17: TRUE | BM17: TRUE | BN17: TRUE | BO17: TRUE | BP17: TRUE | BQ17: TRUE | BR17: TRUE | BS17: TRUE | BT17: TRUE | BU17: TRUE | BV17: TRUE | BW17: TRUE | BX17: TRUE | BY17: TRUE | BZ17: TRUE | CA17: TRUE | CB17: TRUE | CC17: TRUE | CD17: TRUE | CE17: TRUE | CF17: TRUE | CG17: TRUE | CH17: TRUE | CI17: TRUE | CJ17: FALSE | CK17: TRUE | CL17: TRUE | CM17: TRUE | CN17: FALSE | CO17: FALSE | CP17: FALSE | CQ17: FALSE | CR17: FALSE | CS17: FALSE | CT17: TRUE | CU17: TRUE | CV17: TRUE | CW17: TRUE | CX17: TRUE | CY17: TRUE | CZ17: TRUE | DA17: TRUE | DB17: TRUE | DC17: TRUE | DD17: TRUE | DE17: TRUE | DF17: TRUE | DG17: TRUE | DH17: TRUE | DI17: TRUE | DJ17: TRUE | DK17: TRUE | DL17: TRUE | DM17: TRUE
A18: 8 | B18: {=IF(AND(C8:DM8=TRUE), TRUE, FALSE)} -> FALSE | C18: {='Pull Db Dbeaver '!A8:DK8='Pull Data File'!A8:DK8} -> TRUE | D18: TRUE | E18: TRUE | F18: TRUE | G18: TRUE | H18: TRUE | I18: TRUE | J18: TRUE | K18: TRUE | L18: TRUE | M18: TRUE | N18: TRUE | O18: TRUE | P18: TRUE | Q18: TRUE | R18: TRUE | S18: TRUE | T18: TRUE | U18: TRUE | V18: TRUE | W18: TRUE | X18: TRUE | Y18: TRUE | Z18: TRUE | AA18: TRUE | AB18: TRUE | AC18: FALSE | AD18: FALSE | AE18: FALSE | AF18: TRUE | AG18: TRUE | AH18: TRUE | AI18: TRUE | AJ18: TRUE | AK18: TRUE | AL18: TRUE | AM18: TRUE | AN18: TRUE | AO18: TRUE | AP18: TRUE | AQ18: TRUE | AR18: TRUE | AS18: TRUE | AT18: TRUE | AU18: TRUE | AV18: TRUE | AW18: TRUE | AX18: TRUE | AY18: TRUE | AZ18: TRUE | BA18: TRUE | BB18: TRUE | BC18: TRUE | BD18: TRUE | BE18: TRUE | BF18: TRUE | BG18: TRUE | BH18: TRUE | BI18: TRUE | BJ18: TRUE | BK18: TRUE | BL18: TRUE | BM18: TRUE | BN18: TRUE | BO18: TRUE | BP18: TRUE | BQ18: TRUE | BR18: TRUE | BS18: TRUE | BT18: TRUE | BU18: TRUE | BV18: TRUE | BW18: TRUE | BX18: TRUE | BY18: TRUE | BZ18: TRUE | CA18: TRUE | CB18: TRUE | CC18: TRUE | CD18: TRUE | CE18: TRUE | CF18: TRUE | CG18: TRUE | CH18: TRUE | CI18: TRUE | CJ18: FALSE | CK18: TRUE | CL18: TRUE | CM18: TRUE | CN18: FALSE | CO18: FALSE | CP18: FALSE | CQ18: FALSE | CR18: FALSE | CS18: FALSE | CT18: TRUE | CU18: TRUE | CV18: TRUE | CW18: TRUE | CX18: TRUE | CY18: TRUE | CZ18: TRUE | DA18: TRUE | DB18: TRUE | DC18: TRUE | DD18: TRUE | DE18: TRUE | DF18: TRUE | DG18: TRUE | DH18: TRUE | DI18: TRUE | DJ18: TRUE | DK18: TRUE | DL18: TRUE | DM18: TRUE
A19: 9 | B19: {=IF(AND(C9:DM9=TRUE), TRUE, FALSE)} -> FALSE | C19: {='Pull Db Dbeaver '!A9:DK9='Pull Data File'!A9:DK9} -> TRUE | D19: TRUE | E19: TRUE | F19: TRUE | G19: TRUE | H19: TRUE | I19: TRUE | J19: TRUE | K19: TRUE | L19: TRUE | M19: TRUE | N19: TRUE | O19: TRUE | P19: TRUE | Q19: TRUE | R19: TRUE | S19: TRUE | T19: TRUE | U19: TRUE | V19: TRUE | W19: TRUE | X19: TRUE | Y19: TRUE | Z19: TRUE | AA19: TRUE | AB19: TRUE | AC19: FALSE | AD19: FALSE | AE19: FALSE | AF19: TRUE | AG19: TRUE | AH19: TRUE | AI19: TRUE | AJ19: TRUE | AK19: TRUE | AL19: TRUE | AM19: TRUE | AN19: TRUE | AO19: TRUE | AP19: TRUE | AQ19: TRUE | AR19: TRUE | AS19: TRUE | AT19: TRUE | AU19: TRUE | AV19: TRUE | AW19: TRUE | AX19: TRUE | AY19: TRUE | AZ19: TRUE | BA19: TRUE | BB19: TRUE | BC19: TRUE | BD19: TRUE | BE19: TRUE | BF19: TRUE | BG19: TRUE | BH19: TRUE | BI19: TRUE | BJ19: TRUE | BK19: TRUE | BL19: TRUE | BM19: TRUE | BN19: TRUE | BO19: TRUE | BP19: TRUE | BQ19: TRUE | BR19: TRUE | BS19: TRUE | BT19: TRUE | BU19: TRUE | BV19: TRUE | BW19: TRUE | BX19: TRUE | BY19: TRUE | BZ19: TRUE | CA19: TRUE | CB19: TRUE | CC19: TRUE | CD19: TRUE | CE19: TRUE | CF19: TRUE | CG19: TRUE | CH19: TRUE | CI19: TRUE | CJ19: FALSE | CK19: TRUE | CL19: TRUE | CM19: TRUE | CN19: FALSE | CO19: FALSE | CP19: FALSE | CQ19: FALSE | CR19: FALSE | CS19: FALSE | CT19: TRUE | CU19: TRUE | CV19: TRUE | CW19: TRUE | CX19: TRUE | CY19: TRUE | CZ19: TRUE | DA19: TRUE | DB19: TRUE | DC19: TRUE | DD19: TRUE | DE19: TRUE | DF19: TRUE | DG19: TRUE | DH19: TRUE | DI19: TRUE | DJ19: TRUE | DK19: TRUE | DL19: TRUE | DM19: TRUE
A20: 10 | B20: {=IF(AND(C10:DM10=TRUE), TRUE, FALSE)} -> FALSE | C20: {='Pull Db Dbeaver '!A10:DK10='Pull Data File'!A10:DK10} -> TRUE | D20: TRUE | E20: TRUE | F20: TRUE | G20: TRUE | H20: TRUE | I20: TRUE | J20: TRUE | K20: TRUE | L20: TRUE | M20: TRUE | N20: TRUE | O20: TRUE | P20: TRUE | Q20: TRUE | R20: TRUE | S20: TRUE | T20: TRUE | U20: TRUE | V20: TRUE | W20: TRUE | X20: TRUE | Y20: TRUE | Z20: TRUE | AA20: TRUE | AB20: TRUE | AC20: FALSE | AD20: FALSE | AE20: FALSE | AF20: TRUE | AG20: TRUE | AH20: TRUE | AI20: TRUE | AJ20: TRUE | AK20: TRUE | AL20: TRUE | AM20: TRUE | AN20: TRUE | AO20: TRUE | AP20: TRUE | AQ20: TRUE | AR20: TRUE | AS20: TRUE | AT20: TRUE | AU20: TRUE | AV20: TRUE | AW20: TRUE | AX20: TRUE | AY20: TRUE | AZ20: TRUE | BA20: TRUE | BB20: TRUE | BC20: TRUE | BD20: TRUE | BE20: TRUE | BF20: TRUE | BG20: TRUE | BH20: TRUE | BI20: TRUE | BJ20: TRUE | BK20: TRUE | BL20: TRUE | BM20: TRUE | BN20: TRUE | BO20: TRUE | BP20: TRUE | BQ20: TRUE | BR20: TRUE | BS20: TRUE | BT20: TRUE | BU20: TRUE | BV20: TRUE | BW20: TRUE | BX20: TRUE | BY20: TRUE | BZ20: TRUE | CA20: TRUE | CB20: TRUE | CC20: TRUE | CD20: TRUE | CE20: TRUE | CF20: TRUE | CG20: TRUE | CH20: TRUE | CI20: TRUE | CJ20: FALSE | CK20: TRUE | CL20: TRUE | CM20: TRUE | CN20: FALSE | CO20: FALSE | CP20: FALSE | CQ20: FALSE | CR20: FALSE | CS20: FALSE | CT20: TRUE | CU20: TRUE | CV20: TRUE | CW20: TRUE | CX20: TRUE | CY20: TRUE | CZ20: TRUE | DA20: TRUE | DB20: TRUE | DC20: TRUE | DD20: TRUE | DE20: TRUE | DF20: TRUE | DG20: TRUE | DH20: TRUE | DI20: TRUE | DJ20: TRUE | DK20: TRUE | DL20: TRUE | DM20: TRUE
A21: 11 | B21: {=IF(AND(C11:DM11=TRUE), TRUE, FALSE)} -> FALSE | C21: {='Pull Db Dbeaver '!A11:DK11='Pull Data File'!A11:DK11} -> TRUE | D21: TRUE | E21: TRUE | F21: TRUE | G21: TRUE | H21: TRUE | I21: TRUE | J21: TRUE | K21: TRUE | L21: TRUE | M21: TRUE | N21: TRUE | O21: TRUE | P21: TRUE | Q21: TRUE | R21: TRUE | S21: TRUE | T21: TRUE | U21: TRUE | V21: TRUE | W21: TRUE | X21: TRUE | Y21: TRUE | Z21: TRUE | AA21: TRUE | AB21: TRUE | AC21: FALSE | AD21: FALSE | AE21: FALSE | AF21: TRUE | AG21: TRUE | AH21: TRUE | AI21: TRUE | AJ21: TRUE | AK21: TRUE | AL21: TRUE | AM21: TRUE | AN21: TRUE | AO21: TRUE | AP21: TRUE | AQ21: TRUE | AR21: TRUE | AS21: TRUE | AT21: TRUE | AU21: TRUE | AV21: TRUE | AW21: TRUE | AX21: TRUE | AY21: TRUE | AZ21: TRUE | BA21: TRUE | BB21: TRUE | BC21: TRUE | BD21: TRUE | BE21: TRUE | BF21: TRUE | BG21: TRUE | BH21: TRUE | BI21: TRUE | BJ21: TRUE | BK21: TRUE | BL21: TRUE | BM21: TRUE | BN21: TRUE | BO21: TRUE | BP21: TRUE | BQ21: TRUE | BR21: TRUE | BS21: TRUE | BT21: TRUE | BU21: TRUE | BV21: TRUE | BW21: TRUE | BX21: TRUE | BY21: TRUE | BZ21: TRUE | CA21: TRUE | CB21: TRUE | CC21: TRUE | CD21: TRUE | CE21: TRUE | CF21: TRUE | CG21: TRUE | CH21: TRUE | CI21: TRUE | CJ21: FALSE | CK21: TRUE | CL21: TRUE | CM21: TRUE | CN21: FALSE | CO21: FALSE | CP21: FALSE | CQ21: FALSE | CR21: FALSE | CS21: FALSE | CT21: TRUE | CU21: TRUE | CV21: TRUE | CW21: TRUE | CX21: TRUE | CY21: TRUE | CZ21: TRUE | DA21: TRUE | DB21: TRUE | DC21: TRUE | DD21: TRUE | DE21: TRUE | DF21: TRUE | DG21: TRUE | DH21: TRUE | DI21: TRUE | DJ21: TRUE | DK21: TRUE | DL21: TRUE | DM21: TRUE
A22: 12 | B22: {=IF(AND(C12:DM12=TRUE), TRUE, FALSE)} -> FALSE | C22: {='Pull Db Dbeaver '!A12:DK12='Pull Data File'!A12:DK12} -> TRUE | D22: TRUE | E22: TRUE | F22: TRUE | G22: TRUE | H22: TRUE | I22: TRUE | J22: TRUE | K22: TRUE | L22: TRUE | M22: TRUE | N22: TRUE | O22: TRUE | P22: TRUE | Q22: TRUE | R22: TRUE | S22: TRUE | T22: TRUE | U22: TRUE | V22: TRUE | W22: TRUE | X22: TRUE | Y22: TRUE | Z22: TRUE | AA22: TRUE | AB22: TRUE | AC22: FALSE | AD22: FALSE | AE22: FALSE | AF22: TRUE | AG22: TRUE | AH22: TRUE | AI22: TRUE | AJ22: TRUE | AK22: TRUE | AL22: TRUE | AM22: TRUE | AN22: TRUE | AO22: TRUE | AP22: TRUE | AQ22: TRUE | AR22: TRUE | AS22: TRUE | AT22: TRUE | AU22: TRUE | AV22: TRUE | AW22: TRUE | AX22: TRUE | AY22: TRUE | AZ22: TRUE | BA22: TRUE | BB22: TRUE | BC22: TRUE | BD22: TRUE | BE22: TRUE | BF22: TRUE | BG22: TRUE | BH22: TRUE | BI22: TRUE | BJ22: TRUE | BK22: TRUE | BL22: TRUE | BM22: TRUE | BN22: TRUE | BO22: TRUE | BP22: TRUE | BQ22: TRUE | BR22: TRUE | BS22: TRUE | BT22: TRUE | BU22: TRUE | BV22: TRUE | BW22: TRUE | BX22: TRUE | BY22: TRUE | BZ22: TRUE | CA22: TRUE | CB22: TRUE | CC22: TRUE | CD22: TRUE | CE22: TRUE | CF22: TRUE | CG22: TRUE | CH22: TRUE | CI22: TRUE | CJ22: FALSE | CK22: TRUE | CL22: TRUE | CM22: TRUE | CN22: FALSE | CO22: FALSE | CP22: FALSE | CQ22: FALSE | CR22: FALSE | CS22: FALSE | CT22: TRUE | CU22: TRUE | CV22: TRUE | CW22: TRUE | CX22: TRUE | CY22: TRUE | CZ22: TRUE | DA22: TRUE | DB22: TRUE | DC22: TRUE | DD22: TRUE | DE22: TRUE | DF22: TRUE | DG22: TRUE | DH22: TRUE | DI22: TRUE | DJ22: TRUE | DK22: TRUE | DL22: TRUE | DM22: TRUE
... A25: 15 | B25: {=IF(AND(C15:DM15=TRUE), TRUE, FALSE)} -> FALSE | C25: {='Pull Db Dbeaver '!A15:DK15='Pull Data File'!A15:DK15} -> TRUE | D25: TRUE | E25: TRUE | F25: TRUE | G25: TRUE | H25: TRUE | I25: TRUE | J25: TRUE | K25: TRUE | L25: TRUE | M25: TRUE | N25: TRUE | O25: TRUE | P25: TRUE | Q25: TRUE | R25: TRUE | S25: TRUE | T25: TRUE | U25: TRUE | V25: TRUE | W25: TRUE | X25: TRUE | Y25: TRUE | Z25: TRUE | AA25: TRUE | AB25: TRUE | AC25: FALSE | AD25: FALSE | AE25: FALSE | AF25: TRUE | AG25: TRUE | AH25: TRUE | AI25: TRUE | AJ25: TRUE | AK25: TRUE | AL25: TRUE | AM25: TRUE | AN25: TRUE | AO25: TRUE | AP25: TRUE | AQ25: TRUE | AR25: TRUE | AS25: TRUE | AT25: TRUE | AU25: TRUE | AV25: TRUE | AW25: TRUE | AX25: TRUE | AY25: TRUE | AZ25: TRUE | BA25: TRUE | BB25: TRUE | BC25: TRUE | BD25: TRUE | BE25: TRUE | BF25: TRUE | BG25: TRUE | BH25: TRUE | BI25: TRUE | BJ25: TRUE | BK25: TRUE | BL25: TRUE | BM25: TRUE | BN25: TRUE | BO25: TRUE | BP25: TRUE | BQ25: TRUE | BR25: TRUE | BS25: TRUE | BT25: TRUE | BU25: TRUE | BV25: TRUE | BW25: TRUE | BX25: TRUE | BY25: TRUE | BZ25: TRUE | CA25: TRUE | CB25: TRUE | CC25: TRUE | CD25: TRUE | CE25: TRUE | CF25: TRUE | CG25: TRUE | CH25: TRUE | CI25: TRUE | CJ25: FALSE | CK25: TRUE | CL25: TRUE | CM25: TRUE | CN25: FALSE | CO25: FALSE | CP25: FALSE | CQ25: FALSE | CR25: FALSE | CS25: FALSE | CT25: TRUE | CU25: TRUE | CV25: TRUE | CW25: TRUE | CX25: TRUE | CY25: TRUE | CZ25: TRUE | DA25: TRUE | DB25: TRUE | DC25: TRUE | DD25: TRUE | DE25: TRUE | DF25: TRUE | DG25: TRUE | DH25: TRUE | DI25: TRUE | DJ25: TRUE | DK25: TRUE | DL25: TRUE | DM25: TRUE
A26: 16 | B26: {=IF(AND(C15:DM15=TRUE), TRUE, FALSE)} -> FALSE | C26: {='Pull Db Dbeaver '!A16:DK16='Pull Data File'!A16:DK16} -> TRUE | D26: TRUE | E26: TRUE | F26: TRUE | G26: TRUE | H26: TRUE | I26: TRUE | J26: TRUE | K26: TRUE | L26: TRUE | M26: TRUE | N26: TRUE | O26: TRUE | P26: TRUE | Q26: TRUE | R26: TRUE | S26: TRUE | T26: TRUE | U26: TRUE | V26: TRUE | W26: TRUE | X26: TRUE | Y26: TRUE | Z26: TRUE | AA26: TRUE | AB26: TRUE | AC26: FALSE | AD26: FALSE | AE26: FALSE | AF26: TRUE | AG26: TRUE | AH26: TRUE | AI26: TRUE | AJ26: TRUE | AK26: TRUE | AL26: TRUE | AM26: TRUE | AN26: TRUE | AO26: TRUE | AP26: TRUE | AQ26: TRUE | AR26: TRUE | AS26: TRUE | AT26: TRUE | AU26: TRUE | AV26: TRUE | AW26: TRUE | AX26: TRUE | AY26: TRUE | AZ26: TRUE | BA26: TRUE | BB26: TRUE | BC26: TRUE | BD26: TRUE | BE26: TRUE | BF26: TRUE | BG26: TRUE | BH26: TRUE | BI26: TRUE | BJ26: TRUE | BK26: TRUE | BL26: TRUE | BM26: TRUE | BN26: TRUE | BO26: TRUE | BP26: TRUE | BQ26: TRUE | BR26: TRUE | BS26: TRUE | BT26: TRUE | BU26: TRUE | BV26: TRUE | BW26: TRUE | BX26: TRUE | BY26: TRUE | BZ26: TRUE | CA26: TRUE | CB26: TRUE | CC26: TRUE | CD26: TRUE | CE26: TRUE | CF26: TRUE | CG26: TRUE | CH26: TRUE | CI26: TRUE | CJ26: FALSE | CK26: TRUE | CL26: TRUE | CM26: TRUE | CN26: FALSE | CO26: FALSE | CP26: FALSE | CQ26: FALSE | CR26: FALSE | CS26: FALSE | CT26: TRUE | CU26: TRUE | CV26: TRUE | CW26: TRUE | CX26: TRUE | CY26: TRUE | CZ26: TRUE | DA26: TRUE | DB26: TRUE | DC26: TRUE | DD26: TRUE | DE26: TRUE | DF26: TRUE | DG26: TRUE | DH26: TRUE | DI26: TRUE | DJ26: TRUE | DK26: TRUE | DL26: TRUE | DM26: TRUE
A27: 17 | B27: {=IF(AND(C16:DM16=TRUE), TRUE, FALSE)} -> FALSE | C27: {='Pull Db Dbeaver '!A17:DK17='Pull Data File'!A17:DK17} -> TRUE | D27: TRUE | E27: TRUE | F27: TRUE | G27: TRUE | H27: TRUE | I27: TRUE | J27: TRUE | K27: TRUE | L27: TRUE | M27: TRUE | N27: TRUE | O27: TRUE | P27: TRUE | Q27: TRUE | R27: TRUE | S27: TRUE | T27: TRUE | U27: TRUE | V27: TRUE | W27: TRUE | X27: TRUE | Y27: TRUE | Z27: TRUE | AA27: TRUE | AB27: TRUE | AC27: FALSE | AD27: FALSE | AE27: FALSE | AF27: TRUE | AG27: TRUE | AH27: TRUE | AI27: TRUE | AJ27: TRUE | AK27: TRUE | AL27: TRUE | AM27: TRUE | AN27: TRUE | AO27: TRUE | AP27: TRUE | AQ27: TRUE | AR27: TRUE | AS27: TRUE | AT27: TRUE | AU27: TRUE | AV27: TRUE | AW27: TRUE | AX27: TRUE | AY27: TRUE | AZ27: TRUE | BA27: TRUE | BB27: TRUE | BC27: TRUE | BD27: TRUE | BE27: TRUE | BF27: TRUE | BG27: TRUE | BH27: TRUE | BI27: TRUE | BJ27: TRUE | BK27: TRUE | BL27: TRUE | BM27: TRUE | BN27: TRUE | BO27: TRUE | BP27: TRUE | BQ27: TRUE | BR27: TRUE | BS27: TRUE | BT27: TRUE | BU27: TRUE | BV27: TRUE | BW27: TRUE | BX27: TRUE | BY27: TRUE | BZ27: TRUE | CA27: TRUE | CB27: TRUE | CC27: TRUE | CD27: TRUE | CE27: TRUE | CF27: TRUE | CG27: TRUE | CH27: TRUE | CI27: TRUE | CJ27: FALSE | CK27: TRUE | CL27: TRUE | CM27: TRUE | CN27: FALSE | CO27: FALSE | CP27: FALSE | CQ27: FALSE | CR27: FALSE | CS27: FALSE | CT27: TRUE | CU27: TRUE | CV27: TRUE | CW27: TRUE | CX27: TRUE | CY27: TRUE | CZ27: TRUE | DA27: TRUE | DB27: TRUE | DC27: TRUE | DD27: TRUE | DE27: TRUE | DF27: TRUE | DG27: TRUE | DH27: TRUE | DI27: TRUE | DJ27: TRUE | DK27: TRUE | DL27: TRUE | DM27: TRUE
A28: 18 | B28: {=IF(AND(C17:DM17=TRUE), TRUE, FALSE)} -> FALSE | C28: {='Pull Db Dbeaver '!A18:DK18='Pull Data File'!A18:DK18} -> TRUE | D28: TRUE | E28: TRUE | F28: TRUE | G28: TRUE | H28: TRUE | I28: TRUE | J28: TRUE | K28: TRUE | L28: TRUE | M28: TRUE | N28: TRUE | O28: TRUE | P28: TRUE | Q28: TRUE | R28: TRUE | S28: TRUE | T28: TRUE | U28: TRUE | V28: TRUE | W28: TRUE | X28: TRUE | Y28: TRUE | Z28: TRUE | AA28: TRUE | AB28: TRUE | AC28: FALSE | AD28: FALSE | AE28: FALSE | AF28: TRUE | AG28: TRUE | AH28: TRUE | AI28: TRUE | AJ28: TRUE | AK28: TRUE | AL28: TRUE | AM28: TRUE | AN28: TRUE | AO28: TRUE | AP28: TRUE | AQ28: TRUE | AR28: TRUE | AS28: TRUE | AT28: TRUE | AU28: TRUE | AV28: TRUE | AW28: TRUE | AX28: TRUE | AY28: TRUE | AZ28: TRUE | BA28: TRUE | BB28: TRUE | BC28: TRUE | BD28: TRUE | BE28: TRUE | BF28: TRUE | BG28: TRUE | BH28: TRUE | BI28: TRUE | BJ28: TRUE | BK28: TRUE | BL28: TRUE | BM28: TRUE | BN28: TRUE | BO28: TRUE | BP28: TRUE | BQ28: TRUE | BR28: TRUE | BS28: TRUE | BT28: TRUE | BU28: TRUE | BV28: TRUE | BW28: TRUE | BX28: TRUE | BY28: TRUE | BZ28: TRUE | CA28: TRUE | CB28: TRUE | CC28: TRUE | CD28: TRUE | CE28: TRUE | CF28: TRUE | CG28: TRUE | CH28: TRUE | CI28: TRUE | CJ28: FALSE | CK28: TRUE | CL28: TRUE | CM28: TRUE | CN28: FALSE | CO28: FALSE | CP28: FALSE | CQ28: FALSE | CR28: FALSE | CS28: FALSE | CT28: TRUE | CU28: TRUE | CV28: TRUE | CW28: TRUE | CX28: TRUE | CY28: TRUE | CZ28: TRUE | DA28: TRUE | DB28: TRUE | DC28: TRUE | DD28: TRUE | DE28: TRUE | DF28: TRUE | DG28: TRUE | DH28: TRUE | DI28: TRUE | DJ28: TRUE | DK28: TRUE | DL28: TRUE | DM28: TRUE
A29: 19 | B29: {=IF(AND(C18:DM18=TRUE), TRUE, FALSE)} -> FALSE | C29: {='Pull Db Dbeaver '!A19:DK19='Pull Data File'!A19:DK19} -> TRUE | D29: TRUE | E29: TRUE | F29: TRUE | G29: TRUE | H29: TRUE | I29: TRUE | J29: TRUE | K29: TRUE | L29: TRUE | M29: TRUE | N29: TRUE | O29: TRUE | P29: TRUE | Q29: TRUE | R29: TRUE | S29: TRUE | T29: TRUE | U29: TRUE | V29: TRUE | W29: TRUE | X29: TRUE | Y29: TRUE | Z29: TRUE | AA29: TRUE | AB29: TRUE | AC29: FALSE | AD29: FALSE | AE29: FALSE | AF29: TRUE | AG29: TRUE | AH29: TRUE | AI29: TRUE | AJ29: TRUE | AK29: TRUE | AL29: TRUE | AM29: TRUE | AN29: TRUE | AO29: TRUE | AP29: TRUE | AQ29: TRUE | AR29: TRUE | AS29: TRUE | AT29: TRUE | AU29: TRUE | AV29: TRUE | AW29: TRUE | AX29: TRUE | AY29: TRUE | AZ29: TRUE | BA29: TRUE | BB29: TRUE | BC29: TRUE | BD29: TRUE | BE29: TRUE | BF29: TRUE | BG29: TRUE | BH29: TRUE | BI29: TRUE | BJ29: TRUE | BK29: TRUE | BL29: TRUE | BM29: TRUE | BN29: TRUE | BO29: TRUE | BP29: TRUE | BQ29: TRUE | BR29: TRUE | BS29: TRUE | BT29: TRUE | BU29: TRUE | BV29: TRUE | BW29: TRUE | BX29: TRUE | BY29: TRUE | BZ29: TRUE | CA29: TRUE | CB29: TRUE | CC29: TRUE | CD29: TRUE | CE29: TRUE | CF29: TRUE | CG29: TRUE | CH29: TRUE | CI29: TRUE | CJ29: FALSE | CK29: TRUE | CL29: TRUE | CM29: TRUE | CN29: FALSE | CO29: FALSE | CP29: FALSE | CQ29: FALSE | CR29: FALSE | CS29: FALSE | CT29: TRUE | CU29: TRUE | CV29: TRUE | CW29: TRUE | CX29: TRUE | CY29: TRUE | CZ29: TRUE | DA29: TRUE | DB29: TRUE | DC29: TRUE | DD29: TRUE | DE29: TRUE | DF29: TRUE | DG29: TRUE | DH29: TRUE | DI29: TRUE | DJ29: TRUE | DK29: TRUE | DL29: TRUE | DM29: TRUE
A30: 20 | B30: {=IF(AND(C19:DM19=TRUE), TRUE, FALSE)} -> FALSE | C30: {='Pull Db Dbeaver '!A20:DK20='Pull Data File'!A20:DK20} -> TRUE | D30: TRUE | E30: TRUE | F30: TRUE | G30: TRUE | H30: TRUE | I30: TRUE | J30: TRUE | K30: TRUE | L30: TRUE | M30: TRUE | N30: TRUE | O30: TRUE | P30: TRUE | Q30: TRUE | R30: TRUE | S30: TRUE | T30: TRUE | U30: TRUE | V30: TRUE | W30: TRUE | X30: TRUE | Y30: TRUE | Z30: TRUE | AA30: TRUE | AB30: TRUE | AC30: FALSE | AD30: FALSE | AE30: FALSE | AF30: TRUE | AG30: TRUE | AH30: TRUE | AI30: TRUE | AJ30: TRUE | AK30: TRUE | AL30: TRUE | AM30: TRUE | AN30: TRUE | AO30: TRUE | AP30: TRUE | AQ30: TRUE | AR30: TRUE | AS30: TRUE | AT30: TRUE | AU30: TRUE | AV30: TRUE | AW30: TRUE | AX30: TRUE | AY30: TRUE | AZ30: TRUE | BA30: TRUE | BB30: TRUE | BC30: TRUE | BD30: TRUE | BE30: TRUE | BF30: TRUE | BG30: TRUE | BH30: TRUE | BI30: TRUE | BJ30: TRUE | BK30: TRUE | BL30: TRUE | BM30: TRUE | BN30: TRUE | BO30: TRUE | BP30: TRUE | BQ30: TRUE | BR30: TRUE | BS30: TRUE | BT30: TRUE | BU30: TRUE | BV30: TRUE | BW30: TRUE | BX30: TRUE | BY30: TRUE | BZ30: TRUE | CA30: TRUE | CB30: TRUE | CC30: TRUE | CD30: TRUE | CE30: TRUE | CF30: TRUE | CG30: TRUE | CH30: TRUE | CI30: TRUE | CJ30: FALSE | CK30: TRUE | CL30: TRUE | CM30: TRUE | CN30: FALSE | CO30: FALSE | CP30: FALSE | CQ30: FALSE | CR30: FALSE | CS30: FALSE | CT30: TRUE | CU30: TRUE | CV30: TRUE | CW30: TRUE | CX30: TRUE | CY30: TRUE | CZ30: TRUE | DA30: TRUE | DB30: TRUE | DC30: TRUE | DD30: TRUE | DE30: TRUE | DF30: TRUE | DG30: TRUE | DH30: TRUE | DI30: TRUE | DJ30: TRUE | DK30: TRUE | DL30: TRUE | DM30: TRUE
A31: 21 | B31: {=IF(AND(C20:DM20=TRUE), TRUE, FALSE)} -> FALSE | C31: {='Pull Db Dbeaver '!A21:DK21='Pull Data File'!A21:DK21} -> TRUE | D31: TRUE | E31: TRUE | F31: TRUE | G31: TRUE | H31: TRUE | I31: TRUE | J31: TRUE | K31: TRUE | L31: TRUE | M31: TRUE | N31: TRUE | O31: TRUE | P31: TRUE | Q31: TRUE | R31: TRUE | S31: TRUE | T31: TRUE | U31: TRUE | V31: TRUE | W31: TRUE | X31: TRUE | Y31: TRUE | Z31: TRUE | AA31: TRUE | AB31: TRUE | AC31: FALSE | AD31: FALSE | AE31: FALSE | AF31: TRUE | AG31: TRUE | AH31: TRUE | AI31: TRUE | AJ31: TRUE | AK31: TRUE | AL31: TRUE | AM31: TRUE | AN31: TRUE | AO31: TRUE | AP31: TRUE | AQ31: TRUE | AR31: TRUE | AS31: TRUE | AT31: TRUE | AU31: TRUE | AV31: TRUE | AW31: TRUE | AX31: TRUE | AY31: TRUE | AZ31: TRUE | BA31: TRUE | BB31: TRUE | BC31: TRUE | BD31: TRUE | BE31: TRUE | BF31: TRUE | BG31: TRUE | BH31: TRUE | BI31: TRUE | BJ31: TRUE | BK31: TRUE | BL31: TRUE | BM31: TRUE | BN31: TRUE | BO31: TRUE | BP31: TRUE | BQ31: TRUE | BR31: TRUE | BS31: TRUE | BT31: TRUE | BU31: TRUE | BV31: TRUE | BW31: TRUE | BX31: TRUE | BY31: TRUE | BZ31: TRUE | CA31: TRUE | CB31: TRUE | CC31: TRUE | CD31: TRUE | CE31: TRUE | CF31: TRUE | CG31: TRUE | CH31: TRUE | CI31: TRUE | CJ31: FALSE | CK31: TRUE | CL31: TRUE | CM31: TRUE | CN31: FALSE | CO31: FALSE | CP31: FALSE | CQ31: FALSE | CR31: FALSE | CS31: FALSE | CT31: TRUE | CU31: TRUE | CV31: TRUE | CW31: TRUE | CX31: TRUE | CY31: TRUE | CZ31: TRUE | DA31: TRUE | DB31: TRUE | DC31: TRUE | DD31: TRUE | DE31: TRUE | DF31: TRUE | DG31: TRUE | DH31: TRUE | DI31: TRUE | DJ31: TRUE | DK31: TRUE | DL31: TRUE | DM31: TRUE
A32: 22 | B32: {=IF(AND(C21:DM21=TRUE), TRUE, FALSE)} -> FALSE | C32: {='Pull Db Dbeaver '!A22:DK22='Pull Data File'!A22:DK22} -> TRUE | D32: TRUE | E32: TRUE | F32: TRUE | G32: TRUE | H32: TRUE | I32: TRUE | J32: TRUE | K32: TRUE | L32: TRUE | M32: TRUE | N32: TRUE | O32: TRUE | P32: TRUE | Q32: TRUE | R32: TRUE | S32: TRUE | T32: TRUE | U32: TRUE | V32: TRUE | W32: TRUE | X32: TRUE | Y32: TRUE | Z32: TRUE | AA32: TRUE | AB32: TRUE | AC32: FALSE | AD32: FALSE | AE32: FALSE | AF32: TRUE | AG32: TRUE | AH32: TRUE | AI32: TRUE | AJ32: TRUE | AK32: TRUE | AL32: TRUE | AM32: TRUE | AN32: TRUE | AO32: TRUE | AP32: TRUE | AQ32: TRUE | AR32: TRUE | AS32: TRUE | AT32: TRUE | AU32: TRUE | AV32: TRUE | AW32: TRUE | AX32: TRUE | AY32: TRUE | AZ32: TRUE | BA32: TRUE | BB32: TRUE | BC32: TRUE | BD32: TRUE | BE32: TRUE | BF32: TRUE | BG32: TRUE | BH32: TRUE | BI32: TRUE | BJ32: TRUE | BK32: TRUE | BL32: TRUE | BM32: TRUE | BN32: TRUE | BO32: TRUE | BP32: TRUE | BQ32: TRUE | BR32: TRUE | BS32: TRUE | BT32: TRUE | BU32: TRUE | BV32: TRUE | BW32: TRUE | BX32: TRUE | BY32: TRUE | BZ32: TRUE | CA32: TRUE | CB32: TRUE | CC32: TRUE | CD32: TRUE | CE32: TRUE | CF32: TRUE | CG32: TRUE | CH32: TRUE | CI32: TRUE | CJ32: FALSE | CK32: TRUE | CL32: TRUE | CM32: TRUE | CN32: FALSE | CO32: FALSE | CP32: FALSE | CQ32: FALSE | CR32: FALSE | CS32: FALSE | CT32: TRUE | CU32: TRUE | CV32: TRUE | CW32: TRUE | CX32: TRUE | CY32: TRUE | CZ32: TRUE | DA32: TRUE | DB32: TRUE | DC32: TRUE | DD32: TRUE | DE32: TRUE | DF32: TRUE | DG32: TRUE | DH32: TRUE | DI32: TRUE | DJ32: TRUE | DK32: TRUE | DL32: TRUE | DM32: TRUE
A33: 23 | B33: {=IF(AND(C22:DM22=TRUE), TRUE, FALSE)} -> FALSE | C33: {='Pull Db Dbeaver '!A23:DK23='Pull Data File'!A23:DK23} -> TRUE | D33: TRUE | E33: TRUE | F33: TRUE | G33: TRUE | H33: TRUE | I33: TRUE | J33: TRUE | K33: TRUE | L33: TRUE | M33: TRUE | N33: TRUE | O33: TRUE | P33: TRUE | Q33: TRUE | R33: TRUE | S33: TRUE | T33: TRUE | U33: TRUE | V33: TRUE | W33: TRUE | X33: TRUE | Y33: TRUE | Z33: TRUE | AA33: TRUE | AB33: TRUE | AC33: FALSE | AD33: FALSE | AE33: FALSE | AF33: TRUE | AG33: TRUE | AH33: TRUE | AI33: TRUE | AJ33: TRUE | AK33: TRUE | AL33: TRUE | AM33: TRUE | AN33: TRUE | AO33: TRUE | AP33: TRUE | AQ33: TRUE | AR33: TRUE | AS33: TRUE | AT33: TRUE | AU33: TRUE | AV33: TRUE | AW33: TRUE | AX33: TRUE | AY33: TRUE | AZ33: TRUE | BA33: TRUE | BB33: TRUE | BC33: TRUE | BD33: TRUE | BE33: TRUE | BF33: TRUE | BG33: TRUE | BH33: TRUE | BI33: TRUE | BJ33: TRUE | BK33: TRUE | BL33: TRUE | BM33: TRUE | BN33: TRUE | BO33: TRUE | BP33: TRUE | BQ33: TRUE | BR33: TRUE | BS33: TRUE | BT33: TRUE | BU33: TRUE | BV33: TRUE | BW33: TRUE | BX33: TRUE | BY33: TRUE | BZ33: TRUE | CA33: TRUE | CB33: TRUE | CC33: TRUE | CD33: TRUE | CE33: TRUE | CF33: TRUE | CG33: TRUE | CH33: TRUE | CI33: TRUE | CJ33: FALSE | CK33: TRUE | CL33: TRUE | CM33: TRUE | CN33: FALSE | CO33: FALSE | CP33: FALSE | CQ33: FALSE | CR33: FALSE | CS33: FALSE | CT33: TRUE | CU33: TRUE | CV33: TRUE | CW33: TRUE | CX33: TRUE | CY33: TRUE | CZ33: TRUE | DA33: TRUE | DB33: TRUE | DC33: TRUE | DD33: TRUE | DE33: TRUE | DF33: TRUE | DG33: TRUE | DH33: TRUE | DI33: TRUE | DJ33: TRUE | DK33: TRUE | DL33: TRUE | DM33: TRUE
A34: 24 | B34: {=IF(AND(C23:DM23=TRUE), TRUE, FALSE)} -> FALSE | C34: {='Pull Db Dbeaver '!A24:DK24='Pull Data File'!A24:DK24} -> TRUE | D34: TRUE | E34: TRUE | F34: TRUE | G34: TRUE | H34: TRUE | I34: TRUE | J34: TRUE | K34: TRUE | L34: TRUE | M34: TRUE | N34: TRUE | O34: TRUE | P34: TRUE | Q34: TRUE | R34: TRUE | S34: TRUE | T34: TRUE | U34: TRUE | V34: TRUE | W34: TRUE | X34: TRUE | Y34: TRUE | Z34: TRUE | AA34: TRUE | AB34: TRUE | AC34: FALSE | AD34: FALSE | AE34: FALSE | AF34: TRUE | AG34: TRUE | AH34: TRUE | AI34: TRUE | AJ34: TRUE | AK34: TRUE | AL34: TRUE | AM34: TRUE | AN34: TRUE | AO34: TRUE | AP34: TRUE | AQ34: TRUE | AR34: TRUE | AS34: TRUE | AT34: TRUE | AU34: TRUE | AV34: TRUE | AW34: TRUE | AX34: TRUE | AY34: TRUE | AZ34: TRUE | BA34: TRUE | BB34: TRUE | BC34: TRUE | BD34: TRUE | BE34: TRUE | BF34: TRUE | BG34: TRUE | BH34: TRUE | BI34: TRUE | BJ34: TRUE | BK34: TRUE | BL34: TRUE | BM34: TRUE | BN34: TRUE | BO34: TRUE | BP34: TRUE | BQ34: TRUE | BR34: TRUE | BS34: TRUE | BT34: TRUE | BU34: TRUE | BV34: TRUE | BW34: TRUE | BX34: TRUE | BY34: TRUE | BZ34: TRUE | CA34: TRUE | CB34: TRUE | CC34: TRUE | CD34: TRUE | CE34: TRUE | CF34: TRUE | CG34: TRUE | CH34: TRUE | CI34: TRUE | CJ34: FALSE | CK34: TRUE | CL34: TRUE | CM34: TRUE | CN34: FALSE | CO34: FALSE | CP34: FALSE | CQ34: FALSE | CR34: FALSE | CS34: FALSE | CT34: TRUE | CU34: TRUE | CV34: TRUE | CW34: TRUE | CX34: TRUE | CY34: TRUE | CZ34: TRUE | DA34: TRUE | DB34: TRUE | DC34: TRUE | DD34: TRUE | DE34: TRUE | DF34: TRUE | DG34: TRUE | DH34: TRUE | DI34: TRUE | DJ34: TRUE | DK34: TRUE | DL34: TRUE | DM34: TRUE
A35: 25 | B35: {=IF(AND(C24:DM24=TRUE), TRUE, FALSE)} -> FALSE | C35: {='Pull Db Dbeaver '!A25:DK25='Pull Data File'!A25:DK25} -> TRUE | D35: TRUE | E35: TRUE | F35: TRUE | G35: TRUE | H35: TRUE | I35: TRUE | J35: TRUE | K35: TRUE | L35: TRUE | M35: TRUE | N35: TRUE | O35: TRUE | P35: TRUE | Q35: TRUE | R35: TRUE | S35: TRUE | T35: TRUE | U35: TRUE | V35: TRUE | W35: TRUE | X35: TRUE | Y35: TRUE | Z35: TRUE | AA35: TRUE | AB35: TRUE | AC35: FALSE | AD35: FALSE | AE35: FALSE | AF35: TRUE | AG35: TRUE | AH35: TRUE | AI35: TRUE | AJ35: TRUE | AK35: TRUE | AL35: TRUE | AM35: TRUE | AN35: TRUE | AO35: TRUE | AP35: TRUE | AQ35: TRUE | AR35: TRUE | AS35: TRUE | AT35: TRUE | AU35: TRUE | AV35: TRUE | AW35: TRUE | AX35: TRUE | AY35: TRUE | AZ35: TRUE | BA35: TRUE | BB35: TRUE | BC35: TRUE | BD35: TRUE | BE35: TRUE | BF35: TRUE | BG35: TRUE | BH35: TRUE | BI35: TRUE | BJ35: TRUE | BK35: TRUE | BL35: TRUE | BM35: TRUE | BN35: TRUE | BO35: TRUE | BP35: TRUE | BQ35: TRUE | BR35: TRUE | BS35: TRUE | BT35: TRUE | BU35: TRUE | BV35: TRUE | BW35: TRUE | BX35: TRUE | BY35: TRUE | BZ35: TRUE | CA35: TRUE | CB35: TRUE | CC35: TRUE | CD35: TRUE | CE35: TRUE | CF35: TRUE | CG35: TRUE | CH35: TRUE | CI35: TRUE | CJ35: FALSE | CK35: TRUE | CL35: TRUE | CM35: TRUE | CN35: FALSE | CO35: FALSE | CP35: FALSE | CQ35: FALSE | CR35: FALSE | CS35: FALSE | CT35: TRUE | CU35: TRUE | CV35: TRUE | CW35: TRUE | CX35: TRUE | CY35: TRUE | CZ35: TRUE | DA35: TRUE | DB35: TRUE | DC35: TRUE | DD35: TRUE | DE35: TRUE | DF35: TRUE | DG35: TRUE | DH35: TRUE | DI35: TRUE | DJ35: TRUE | DK35: TRUE | DL35: TRUE | DM35: TRUE
A36: 26 | B36: {=IF(AND(C25:DM25=TRUE), TRUE, FALSE)} -> FALSE | C36: {='Pull Db Dbeaver '!A26:DK26='Pull Data File'!A26:DK26} -> TRUE | D36: TRUE | E36: TRUE | F36: TRUE | G36: TRUE | H36: TRUE | I36: TRUE | J36: TRUE | K36: TRUE | L36: TRUE | M36: TRUE | N36: TRUE | O36: TRUE | P36: TRUE | Q36: TRUE | R36: TRUE | S36: TRUE | T36: TRUE | U36: TRUE | V36: TRUE | W36: TRUE | X36: TRUE | Y36: TRUE | Z36: TRUE | AA36: TRUE | AB36: TRUE | AC36: FALSE | AD36: FALSE | AE36: FALSE | AF36: TRUE | AG36: TRUE | AH36: TRUE | AI36: TRUE | AJ36: TRUE | AK36: TRUE | AL36: TRUE | AM36: TRUE | AN36: TRUE | AO36: TRUE | AP36: TRUE | AQ36: TRUE | AR36: TRUE | AS36: TRUE | AT36: TRUE | AU36: TRUE | AV36: TRUE | AW36: TRUE | AX36: TRUE | AY36: TRUE | AZ36: TRUE | BA36: TRUE | BB36: TRUE | BC36: TRUE | BD36: TRUE | BE36: TRUE | BF36: TRUE | BG36: TRUE | BH36: TRUE | BI36: TRUE | BJ36: TRUE | BK36: TRUE | BL36: TRUE | BM36: TRUE | BN36: TRUE | BO36: TRUE | BP36: TRUE | BQ36: TRUE | BR36: TRUE | BS36: TRUE | BT36: TRUE | BU36: TRUE | BV36: TRUE | BW36: TRUE | BX36: TRUE | BY36: TRUE | BZ36: TRUE | CA36: TRUE | CB36: TRUE | CC36: TRUE | CD36: TRUE | CE36: TRUE | CF36: TRUE | CG36: TRUE | CH36: TRUE | CI36: TRUE | CJ36: FALSE | CK36: TRUE | CL36: TRUE | CM36: TRUE | CN36: FALSE | CO36: FALSE | CP36: FALSE | CQ36: FALSE | CR36: FALSE | CS36: FALSE | CT36: TRUE | CU36: TRUE | CV36: TRUE | CW36: TRUE | CX36: TRUE | CY36: TRUE | CZ36: TRUE | DA36: TRUE | DB36: TRUE | DC36: TRUE | DD36: TRUE | DE36: TRUE | DF36: TRUE | DG36: TRUE | DH36: TRUE | DI36: TRUE | DJ36: TRUE | DK36: TRUE | DL36: TRUE | DM36: TRUE
A37: 27 | B37: {=IF(AND(C26:DM26=TRUE), TRUE, FALSE)} -> FALSE | C37: {='Pull Db Dbeaver '!A27:DK27='Pull Data File'!A27:DK27} -> TRUE | D37: TRUE | E37: TRUE | F37: TRUE | G37: TRUE | H37: TRUE | I37: TRUE | J37: TRUE | K37: TRUE | L37: TRUE | M37: TRUE | N37: TRUE | O37: TRUE | P37: TRUE | Q37: TRUE | R37: TRUE | S37: TRUE | T37: TRUE | U37: TRUE | V37: TRUE | W37: TRUE | X37: TRUE | Y37: TRUE | Z37: TRUE | AA37: TRUE | AB37: TRUE | AC37: FALSE | AD37: FALSE | AE37: FALSE | AF37: TRUE | AG37: TRUE | AH37: TRUE | AI37: TRUE | AJ37: TRUE | AK37: TRUE | AL37: TRUE | AM37: TRUE | AN37: TRUE | AO37: TRUE | AP37: TRUE | AQ37: TRUE | AR37: TRUE | AS37: TRUE | AT37: TRUE | AU37: TRUE | AV37: TRUE | AW37: TRUE | AX37: TRUE | AY37: TRUE | AZ37: TRUE | BA37: TRUE | BB37: TRUE | BC37: TRUE | BD37: TRUE | BE37: TRUE | BF37: TRUE | BG37: TRUE | BH37: TRUE | BI37: TRUE | BJ37: TRUE | BK37: TRUE | BL37: TRUE | BM37: TRUE | BN37: TRUE | BO37: TRUE | BP37: TRUE | BQ37: TRUE | BR37: TRUE | BS37: TRUE | BT37: TRUE | BU37: TRUE | BV37: TRUE | BW37: TRUE | BX37: TRUE | BY37: TRUE | BZ37: TRUE | CA37: TRUE | CB37: TRUE | CC37: TRUE | CD37: TRUE | CE37: TRUE | CF37: TRUE | CG37: TRUE | CH37: TRUE | CI37: TRUE | CJ37: FALSE | CK37: TRUE | CL37: TRUE | CM37: TRUE | CN37: FALSE | CO37: FALSE | CP37: FALSE | CQ37: FALSE | CR37: FALSE | CS37: FALSE | CT37: TRUE | CU37: TRUE | CV37: TRUE | CW37: TRUE | CX37: TRUE | CY37: TRUE | CZ37: TRUE | DA37: TRUE | DB37: TRUE | DC37: TRUE | DD37: TRUE | DE37: TRUE | DF37: TRUE | DG37: TRUE | DH37: TRUE | DI37: TRUE | DJ37: TRUE | DK37: TRUE | DL37: TRUE | DM37: TRUE
... A40: 30 | B40: {=IF(AND(C29:DM29=TRUE), TRUE, FALSE)} -> FALSE | C40: {='Pull Db Dbeaver '!A30:DK30='Pull Data File'!A30:DK30} -> TRUE | D40: TRUE | E40: TRUE | F40: TRUE | G40: TRUE | H40: TRUE | I40: TRUE | J40: TRUE | K40: TRUE | L40: TRUE | M40: TRUE | N40: TRUE | O40: TRUE | P40: TRUE | Q40: TRUE | R40: TRUE | S40: TRUE | T40: TRUE | U40: TRUE | V40: TRUE | W40: TRUE | X40: TRUE | Y40: TRUE | Z40: TRUE | AA40: TRUE | AB40: TRUE | AC40: FALSE | AD40: FALSE | AE40: FALSE | AF40: TRUE | AG40: TRUE | AH40: TRUE | AI40: TRUE | AJ40: TRUE | AK40: TRUE | AL40: TRUE | AM40: TRUE | AN40: TRUE | AO40: TRUE | AP40: TRUE | AQ40: TRUE | AR40: TRUE | AS40: TRUE | AT40: TRUE | AU40: TRUE | AV40: TRUE | AW40: TRUE | AX40: TRUE | AY40: TRUE | AZ40: TRUE | BA40: TRUE | BB40: TRUE | BC40: TRUE | BD40: TRUE | BE40: TRUE | BF40: TRUE | BG40: TRUE | BH40: TRUE | BI40: TRUE | BJ40: TRUE | BK40: TRUE | BL40: TRUE | BM40: TRUE | BN40: TRUE | BO40: TRUE | BP40: TRUE | BQ40: TRUE | BR40: TRUE | BS40: TRUE | BT40: TRUE | BU40: TRUE | BV40: TRUE | BW40: TRUE | BX40: TRUE | BY40: TRUE | BZ40: TRUE | CA40: TRUE | CB40: TRUE | CC40: TRUE | CD40: TRUE | CE40: TRUE | CF40: TRUE | CG40: TRUE | CH40: TRUE | CI40: TRUE | CJ40: FALSE | CK40: TRUE | CL40: TRUE | CM40: TRUE | CN40: FALSE | CO40: FALSE | CP40: FALSE | CQ40: FALSE | CR40: FALSE | CS40: FALSE | CT40: TRUE | CU40: TRUE | CV40: TRUE | CW40: TRUE | CX40: TRUE | CY40: TRUE | CZ40: TRUE | DA40: TRUE | DB40: TRUE | DC40: TRUE | DD40: TRUE | DE40: TRUE | DF40: TRUE | DG40: TRUE | DH40: TRUE | DI40: TRUE | DJ40: TRUE | DK40: TRUE | DL40: TRUE | DM40: TRUE
A46: SAMPLE CASE
A47: "KBANK" | B47: "0000000005" | C47: "บจก. ณรกฤต " | D47: "NARAKRIT CO.,LTD." | E47: "บจก." | F47: "ณรกฤต" | G47: "" | H47: "" | I47: "CO.,LTD." | J47: "NARAKRIT" | K47: "" | L47: "" | M47: "1" | N47: "หนังสือรับรองการจดทะเบียน" | O47: "0105858568211" | P47: " " | Q47: " " | R47: "0601" | S47: "บริษัทจำกัด" | T47: "005022706" | U47: "การค้าปลีกเครื่องมือและอุปกรณ์ทางการแพทย์รวมทั้งเครื่องใช้ปฐมพยาบาล (ยกเว้น ทันตกรรม)" | V47: "" | W47: "" | X47: "น.ส. นานาวรรณก ศุภพิธXX" | Y47: "0813867187" | Z47: "sirirat.sus@kasikornbank.com" | AA47: " " | AB47: " " | AC47: " " | AD47: "" | AE47: "" | AF47: "68-63" | AG47: "." | AH47: "" | AI47: "" | AJ47: "" | AK47: "" | AL47: "ตานาว 5" | AM47: "วาลยำเฬิฬชษาป" | AN47: "วัดบวรนิเวศ" | AO47: "พระนคร" | AP47: "กทม." | AQ47: "10200" | AR47: "TH" | AS47: "68-63 ค.ตานาว 5 ฃ.วาลยำเฬิฬชษาป ฮ.ฤัยฅฤวฬิเฤฌ" | AT47: "อ.พระนคร จ.กทม. 10200" | AU47: "" | AV47: "" | AW47: "61" | AX47: "" | AY47: "" | AZ47: "" | BA47: "" | BB47: "" | BC47: "ฒุดุฏฤิอ14" | BD47: "ฒุดุฏฤิอ" | BE47: "พระโขนงเหนือ" | BF47: "วัฒนา" | BG47: "กทม." | BH47: "10110" | BI47: "TH" | BJ47: "61 ค.ฒุดุฏฤิอ14 ฃ.ฒุดุฏฤิอ ฮ.หวะโดฬปเบฬืต" | BK47: "อ.วัฒนา จ.กทม. 10110" | BL47: "" | BM47: "" | BN47: "" | BO47: "" | BP47: "" | BQ47: "" | BR47: "" | BS47: "" | BT47: "" | BU47: "" | BV47: "" | BW47: "" | BX47: "" | BY47: "" | BZ47: "" | CA47: "" | CB47: "" | CC47: "027240728-1" | CD47: "" | CE47: "" | CF47: "" | CG47: "sjkarjzu@pzcxx.rxo" | CH47: "aก@a.com" | CI47: "" | CJ47: "Customer" | CK47: "001 " | CL47: " " | CM47: " " | CN47: " " | CO47: " " | CP47: " " | CQ47: " " | CR47: "" | CS47: "BATCHUPDATE" | CT47: "2023-10-18" | CU47: "09:50:32 " | CV47: "5" | CW47: "Y" | CX47: "KB000000" | CY47: "2020-02-15" | CZ47: "05:16:03" | DA47: "DUEตามนัด" | DB47: "0.00" | DC47: "" | DD47: "UM" | DE47: "1943-02-05" | DF47: "O" | DG47: "C" | DH47: "" | DI47: "0000138286" | DJ47: "สำนักงานใหญ่" | DK47: "440759"
A48: "KBANK" | B48: "0000000005" | C48: "บจก. ณรกฤต " | D48: "NARAKRIT CO.,LTD." | E48: "บจก." | F48: "ณรกฤต" | G48: "" | H48: "" | I48: "CO.,LTD." | J48: "NARAKRIT" | K48: "" | L48: "" | M48: "1" | N48: "หนังสือรับรองการจดทะเบียน" | O48: "0105858568211" | P48: " " | Q48: " " | R48: "0601" | S48: "บริษัทจำกัด" | T48: "005022706" | U48: "การค้าปลีกเครื่องมือและอุปกรณ์ทางการแพทย์รวมทั้งเครื่องใช้ปฐมพยาบาล (ยกเว้น ทันตกรรม)" | V48: "" | W48: "" | X48: "น.ส. นานาวรรณก ศุภพิธXX" | Y48: "0813867187" | Z48: "sirirat.sus@kasikornbank.com" | AA48: "" | AB48: "" | AC48: "" | AD48: "" | AE48: "" | AF48: "68-63" | AG48: "." | AH48: "" | AI48: "" | AJ48: "" | AK48: "" | AL48: "ตานาว 5" | AM48: "วาลยำเฬิฬชษาป" | AN48: "วัดบวรนิเวศ" | AO48: "พระนคร" | AP48: "กทม." | AQ48: "10200" | AR48: "TH" | AS48: "68-63 ค.ตานาว 5 ฃ.วาลยำเฬิฬชษาป ฮ.ฤัยฅฤวฬิเฤฌ" | AT48: "อ.พระนคร จ.กทม. 10200" | AU48: "" | AV48: "" | AW48: "61" | AX48: "" | AY48: "" | AZ48: "" | BA48: "" | BB48: "" | BC48: "ฒุดุฏฤิอ14" | BD48: "ฒุดุฏฤิอ" | BE48: "พระโขนงเหนือ" | BF48: "วัฒนา" | BG48: "กทม." | BH48: "10110" | BI48: "TH" | BJ48: "61 ค.ฒุดุฏฤิอ14 ฃ.ฒุดุฏฤิอ ฮ.หวะโดฬปเบฬืต" | BK48: "อ.วัฒนา จ.กทม. 10110" | BL48: "" | BM48: "" | BN48: "" | BO48: "" | BP48: "" | BQ48: "" | BR48: "" | BS48: "" | BT48: "" | BU48: "" | BV48: "" | BW48: "" | BX48: "" | BY48: "" | BZ48: "" | CA48: "" | CB48: "" | CC48: "027240728-1" | CD48: "" | CE48: "" | CF48: "" | CG48: "sjkarjzu@pzcxx.rxo" | CH48: "aก@a.com" | CI48: "" | CJ48: "Customer" | CK48: "001 " | CL48: "" | CM48: "" | CN48: "" | CO48: "" | CP48: "" | CQ48: "" | CR48: "" | CS48: "BATCHUPDATE" | CT48: "2023-10-18" | CU48: "09:50:32 " | CV48: "5" | CW48: "Y" | CX48: "KB000000" | CY48: "2020-02-15" | CZ48: "05:16:03" | DA48: "DUEตามนัด" | DB48: "0.00" | DC48: "" | DD48: "UM" | DE48: "1943-02-05" | DF48: "O" | DG48: "C" | DH48: "" | DI48: "0000138286" | DJ48: "สำนักงานใหญ่" | DK48: "440759"
A49: {=A47:DK47=A48:DK48} -> TRUE | B49: TRUE | C49: TRUE | D49: TRUE | E49: TRUE | F49: TRUE | G49: TRUE | H49: TRUE | I49: TRUE | J49: TRUE | K49: TRUE | L49: TRUE | M49: TRUE | N49: TRUE | O49: TRUE | P49: TRUE | Q49: TRUE | R49: TRUE | S49: TRUE | T49: TRUE | U49: TRUE | V49: TRUE | W49: TRUE | X49: TRUE | Y49: TRUE | Z49: TRUE | AA49: FALSE | AB49: FALSE | AC49: FALSE | AD49: TRUE | AE49: TRUE | AF49: TRUE | AG49: TRUE | AH49: TRUE | AI49: TRUE | AJ49: TRUE | AK49: TRUE | AL49: TRUE | AM49: TRUE | AN49: TRUE | AO49: TRUE | AP49: TRUE | AQ49: TRUE | AR49: TRUE | AS49: TRUE | AT49: TRUE | AU49: TRUE | AV49: TRUE | AW49: TRUE | AX49: TRUE | AY49: TRUE | AZ49: TRUE | BA49: TRUE | BB49: TRUE | BC49: TRUE | BD49: TRUE | BE49: TRUE | BF49: TRUE | BG49: TRUE | BH49: TRUE | BI49: TRUE | BJ49: TRUE | BK49: TRUE | BL49: TRUE | BM49: TRUE | BN49: TRUE | BO49: TRUE | BP49: TRUE | BQ49: TRUE | BR49: TRUE | BS49: TRUE | BT49: TRUE | BU49: TRUE | BV49: TRUE | BW49: TRUE | BX49: TRUE | BY49: TRUE | BZ49: TRUE | CA49: TRUE | CB49: TRUE | CC49: TRUE | CD49: TRUE | CE49: TRUE | CF49: TRUE | CG49: TRUE | CH49: TRUE | CI49: TRUE | CJ49: TRUE | CK49: TRUE | CL49: FALSE | CM49: FALSE | CN49: FALSE | CO49: FALSE | CP49: FALSE | CQ49: FALSE | CR49: TRUE | CS49: TRUE | CT49: TRUE | CU49: TRUE | CV49: TRUE | CW49: TRUE | CX49: TRUE | CY49: TRUE | CZ49: TRUE | DA49: TRUE | DB49: TRUE | DC49: TRUE | DD49: TRUE | DE49: TRUE | DF49: TRUE | DG49: TRUE | DH49: TRUE | DI49: TRUE | DJ49: TRUE | DK49: TRUE

Sheet Pull Db Dbeaver 
A1: "KBANK" | B1: "0000000005" | C1: "บจก. ณรกฤต " | D1: "NARAKRIT CO.,LTD." | E1: "บจก." | F1: "ณรกฤต" | G1: "" | H1: "" | I1: "CO.,LTD." | J1: "NARAKRIT" | K1: "" | L1: "" | M1: "1" | N1: "หนังสือรับรองการจดทะเบียน" | O1: "0105858568211" | P1: " " | Q1: " " | R1: "0601" | S1: "บริษัทจำกัด" | T1: "005022706" | U1: "การค้าปลีกเครื่องมือและอุปกรณ์ทางการแพทย์รวมทั้งเครื่องใช้ปฐมพยาบาล (ยกเว้น ทันตกรรม)" | V1: "" | W1: "" | X1: "น.ส. นานาวรรณก ศุภพิธXX" | Y1: "0813867187" | Z1: "sirirat.sus@kasikornbank.com" | AA1: " " | AB1: " " | AC1: " " | AD1: "" | AE1: "" | AF1: "68-63" | AG1: "." | AH1: "" | AI1: "" | AJ1: "" | AK1: "" | AL1: "ตานาว 5" | AM1: "วาลยำเฬิฬชษาป" | AN1: "วัดบวรนิเวศ" | AO1: "พระนคร" | AP1: "กทม." | AQ1: "10200" | AR1: "TH" | AS1: "68-63 ค.ตานาว 5 ฃ.วาลยำเฬิฬชษาป ฮ.ฤัยฅฤวฬิเฤฌ" | AT1: "อ.พระนคร จ.กทม. 10200" | AU1: "" | AV1: "" | AW1: "61" | AX1: "" | AY1: "" | AZ1: "" | BA1: "" | BB1: "" | BC1: "ฒุดุฏฤิอ14" | BD1: "ฒุดุฏฤิอ" | BE1: "พระโขนงเหนือ" | BF1: "วัฒนา" | BG1: "กทม." | BH1: "10110" | BI1: "TH" | BJ1: "61 ค.ฒุดุฏฤิอ14 ฃ.ฒุดุฏฤิอ ฮ.หวะโดฬปเบฬืต" | BK1: "อ.วัฒนา จ.กทม. 10110" | BL1: "" | BM1: "" | BN1: "" | BO1: "" | BP1: "" | BQ1: "" | BR1: "" | BS1: "" | BT1: "" | BU1: "" | BV1: "" | BW1: "" | BX1: "" | BY1: "" | BZ1: "" | CA1: "" | CB1: "" | CC1: "027240728-1" | CD1: "" | CE1: "" | CF1: "" | CG1: "sjkarjzu@pzcxx.rxo" | CH1: "aก@a.com" | CI1: "" | CJ1: "Customer" | CK1: "001 " | CL1: " " | CM1: " " | CN1: " " | CO1: " " | CP1: " " | CQ1: " " | CR1: "" | CS1: "BATCHUPDATE" | CT1: "2023-10-18" | CU1: "09:50:32 " | CV1: "5" | CW1: "Y" | CX1: "KB000000" | CY1: "2020-02-15" | CZ1: "05:16:03" | DA1: "DUEตามนัด" | DB1: "0.00" | DC1: "" | DD1: "UM" | DE1: "1943-02-05" | DF1: "O" | DG1: "C" | DH1: "" | DI1: "0000138286" | DJ1: "สำนักงานใหญ่" | DK1: "440759"
A2: "KBANK" | B2: "0000000013" | C2: "บจก. อับโดเล๊าะ " | D2: "ABDOLOH CO.,LTD." | E2: "บจก." | F2: "อับโดเล๊าะ" | G2: "" | H2: "" | I2: "CO.,LTD." | J2: "ABDOLOH" | K2: "" | L2: "" | M2: "1" | N2: "หนังสือรับรองการจดทะเบียน" | O2: "0105147565174" | P2: " " | Q2: " " | R2: "0601" | S2: "บริษัทจำกัด" | T2: "103100202" | U2: "(นำเข้า) การผลิตเคมีภัณฑ์ที่ใช้สำหรับรักษาความสะอาด" | V2: "" | W2: "" | X2: "" | Y2: "" | Z2: "" | AA2: " " | AB2: " " | AC2: " " | AD2: "" | AE2: "" | AF2: "111" | AG2: "" | AH2: "" | AI2: "" | AJ2: "" | AK2: "" | AL2: "" | AM2: "ฃฬฬหวะวาฏ 8" | AN2: "บางโพงพาง" | AO2: "ยานนาวา" | AP2: "กทม." | AQ2: "10120" | AR2: "TH" | AS2: "111 ฃ.ฃฬฬหวะวาฏ 8 ฮ.ฅาปโหปหาป" | AT2: "อ.ยานนาวา จ.กทม. 10120" | AU2: "" | AV2: "" | AW2: "111" | AX2: "" | AY2: "" | AZ2: "" | BA2: "" | BB2: "" | BC2: "" | BD2: "หวะวาฏ 8" | BE2: "บางโพงพาง" | BF2: "ยานนาวา" | BG2: "กทม." | BH2: "10120" | BI2: "TH" | BJ2: "111 ฃ. หวะวาฏ 8 ฮ. ฅาปโหปหาป" | BK2: "อ. ยานนาวา จ. กทม. 10120" | BL2: "" | BM2: "" | BN2: "111" | BO2: "" | BP2: "" | BQ2: "" | BR2: "" | BS2: "" | BT2: "" | BU2: "หวะวาฏ 8" | BV2: "บางโพงพาง" | BW2: "ยานนาวา" | BX2: "กทม." | BY2: "10120" | BZ2: "TH" | CA2: "111 ฃ.หวะวาฏ 8 ฮ.ฅาปโหปหาป" | CB2: "อ.ยานนาวา จ.กทม. 10120" | CC2: "022067786" | CD2: "" | CE2: "022069405" | CF2: "022067786" | CG2: "" | CH2: " " | CI2: "" | CJ2: "Customer" | CK2: "001 " | CL2: " " | CM2: " " | CN2: " " | CO2: " " | CP2: " " | CQ2: " " | CR2: "" | CS2: "BATCHUPDATE" | CT2: "2023-10-18" | CU2: "09:34:01 " | CV2: "35" | CW2: "Y" | CX2: "KB000000" | CY2: "2020-02-15" | CZ2: "05:16:03" | DA2: "ศ.3" | DB2: "49800000.00" | DC2: "" | DD2: "MB" | DE2: "1967-12-01" | DF2: "O" | DG2: "C" | DH2: "" | DI2: "0003210644" | DJ2: "- สำนักงานใหญ่" | DK2: ""
A3: "KBANK" | B3: "0000000015" | C3: "บจก. รักษาไชย " | D3: "RAKSACHAI CO.,LTD." | E3: "บจก." | F3: "รักษาไชย" | G3: "" | H3: "" | I3: "CO.,LTD." | J3: "RAKSACHAI" | K3: "" | L3: "" | M3: "1" | N3: "หนังสือรับรองการจดทะเบียน" | O3: "0105194567285" | P3: " " | Q3: " " | R3: "0601" | S3: "บริษัทจำกัด" | T3: "005021105" | U3: "การค้าปลีกผลิตภัณฑ์เนื้อสัตว์อื่น และอาหารแช่แข็งสำเร็จรูป" | V3: "" | W3: "" | X3: "น.ส. พุ่มเ บุญญเกีย" | Y3: "0875431726" | Z3: "hatsaya.s@kasikornbank.com" | AA3: " " | AB3: " " | AC3: " " | AD3: "" | AE3: "" | AF3: "980-982" | AG3: "" | AH3: "" | AI3: "ฒิฬณว อาฤเฤตว์ 8" | AJ3: "" | AK3: "95" | AL3: "" | AM3: "ฤิอฟุ" | AN3: "ลุมพินี" | AO3: "ปทุมวัน" | AP3: "กทม." | AQ3: "10330" | AR3: "TH" | AS3: "980-982 ตน.ฒิฬณว อาฤเฤตว์ 8 ลั้ฬ95 ฃ.ฤิอฟุ" | AT3: "ลุมพินี ปทุมวัน กทม. 10330" | AU3: "" | AV3: "" | AW3: "980-982" | AX3: "" | AY3: "" | AZ3: "ฒิฬณว อาฤเฤตว์ 8" | BA3: "" | BB3: "95" | BC3: "" | BD3: "ฤิอฟุ" | BE3: "ลุมพินี" | BF3: "ปทุมวัน" | BG3: "กทม." | BH3: "10330" | BI3: "TH" | BJ3: "980-982 ตน.ฒิฬณว อาฤเฤตว์ 8 ลั้ฬ95 ฃ.ฤิอฟุ" | BK3: "ลุมพินี ปทุมวัน กทม. 10330" | BL3: "" | BM3: "" | BN3: "" | BO3: "" | BP3: "" | BQ3: "" | BR3: "" | BS3: "" | BT3: "" | BU3: "" | BV3: "" | BW3: "" | BX3: "" | BY3: "" | BZ3: "" | CA3: "" | CB3: "" | CC3: "022394312" | CD3: "" | CE3: "" | CF3: "" | CG3: "" | CH3: " " | CI3: "" | CJ3: "Customer" | CK3: "001 " | CL3: " " | CM3: " " | CN3: " " | CO3: " " | CP3: " " | CQ3: " " | CR3: "" | CS3: "BATCHUPDATE" | CT3: "2023-10-18" | CU3: "09:51:06 " | CV3: "0" | CW3: "Y" | CX3: "KB000000" | CY3: "2020-02-15" | CZ3: "05:16:03" | DA3: "ศ.1,ศ.3" | DB3: "0.00" | DC3: "" | DD3: "MB" | DE3: "1980-06-24" | DF3: "O" | DG3: "C" | DH3: "" | DI3: "0009033289" | DJ3: "สำนักงานใหญ่" | DK3: "710984"
