Workbook
Name _56F9DC9755BA473782653E2940F9FormId: "OT154DkJbUmxKRmO3ZFv6wT4ob2Jv5lBseHwcjzz9GdUNVlVQkpaNDdQU0Q5VDhNNFBaUjFOVEJQWSQlQCN0PWcu"
Name _56F9DC9755BA473782653E2940F9ResponseSheet: "Form1"
Name _56F9DC9755BA473782653E2940F9SourceDocId: "{20cff37e-62ca-453c-88e4-ce2eb7538031}"
Name actual: #REF!
Name Analyze1: [3]FIT_GAP!$D$8:$D$10
Name AppInDate: #REF!
Name Application_Acronym_List: '[4]5.Reference Values'!$B:$B
Name Apply_Auto_Ingestion: #REF!
Name Cash_beginning: #REF!
Name Cash_Minimum: #REF!
Name ColumnTitle1: [5]!CashLog[[#Headers],[Date]]
Name Company_name: #REF!
Name Cycle: [6]FixVar!$G$2:$G$8
Name data: OFFSET('[7]Branch Staff'!#REF!,0,0,COUNTA('[7]Branch Staff'!#REF!)-1,COUNTA('[7]Branch Staff'!$A$1:$IV$1))
Name Datum_teller: #REF!
Name Datum_Teller_cash_Reconciliation: #REF!
Name Display_Week: #REF!
Name ExtraCredit: #REF!
Name f: #REF!
Name Fruit: #REF!
Name Grace: #REF!
Name Grace_Bi_Weekly_Installments: #REF!
Name Grace_Months: #REF!
Name IQ_CH: 110000
Name IQ_CQ: 5000
Name IQ_CY: 10000
Name IQ_DAILY: 500000
Name IQ_FH: 100000
Name IQ_FQ: 500
Name IQ_FY: 1000
Name IQ_LTM: 2000
Name IQ_MONTH: 15000
Name IQ_NTM: 6000
Name IQ_WEEK: 50000
Name IQ_YTD: 3000
Name Items: #REF!
Name k: [9]FixVar!$G$2:$G$8
Name LIST: #REF!
Name Meat: #REF!
Name MoreFruit: #REF!
Name MoreItem: #REF!
Name MoreItems: #REF!
Name Print_Area1: #REF!
Name Print_Area2: #REF!
Name Project_Start: #REF!
Name Promotional_Installments: #REF!
Name Report: #REF!
Name Start_Date: #REF!
Name STATUS1: [6]FixVar!$R$2:$R$5
Name SUMExtraCredit: #REF!
Name SUMIF: #REF!
Name SUMIFExtraCredit: #REF!
Name Total: #REF!
Name valuevx: 42.314159

Sheet Version Control
B2: Version | C2: Date | D2: Description | E2: By | R2: Pending Confirm
B3: v00_00_01 | C3: 45268 | D3: Initial | E3: Chonnikan C. | R3: Confirmed
B4: v00_00_02 | C4: 45280 | D4: Updated "Batch 1 - Ingestion Inventory " sheet to only include files/tables required by curation requirement scope Added "Batch 2 - Ingestion Inventory" sheet for files/tables to be cut-off for ingestion team on 27-Dec-2023 | E4: Nonthapatr S. | R4: Pending to provide
B5: v00_00_02 | C5: 45294 | D5: Updated information for Batch 1,2 - KBMF File Reference (From EBAN provided for PlanB) - Table Specification | E5: Chonnikan C. | R5: N/A
B6: v00_00_02 | C6: 45310 | D6: Added 2 tables to Batch 4: - SCM_PRODUCT_MAP - VW_RDT_SCF_CL_ACCT | E6: Nonthapatr S.
B7: v00_00_02 | C7: 45317 | D7: Item removed from scope: - CPACP.DIH.CI1D1166.CRDHD.D.DIH_ENC.TXT (Source: Cardlink TPN) | E7: Thanapol M.
B8: v00_00_03 | C8: 45321 | D8: Added 2 tables to Batch 2 - src_pf_ar_ca_limit_dly_yyyymmdd.txt - common_transaction file.txt | E8: Chonnikan C.
B9: v00_00_04 | C9: 45357 | D9: Updated source table name - GTS (New-Trade): from DBTL4xL10 to DBTL4xL6 Cancelled 3 tables - CPACP.DIH.KB1DH004.CPBMER.Dddmmyy.txt - CPACP.DIH.KB1DH010.OADCTF.DDDMMYY - CPACP.DIH.KB1DH009.KBBMER.DDDMMYY | E9: Tanatchporn S. Chonnikan C.
B10: v00_00_05 | C10: 45363 | D10: Cancelled : DTEADM.VW_STD_INS_EOD_INC (table :ud_vw_std_ins_eod_inc) | E10: Chonnikan C.

Sheet Batch1
A1: View | B1: Column | C1: Desc | D1: Remark | E1: Fix1 | F1: Target | H1: Unique | J1: Status
A2: v_pcb_dep_src_pf_ar_sa_dly | B2: pos_dt | H2: Record Type | J2: clmn_nm_blnk | K2: =_xlfn.CONCAT(COUNTBLANK(B2:B2227)," Field") -> 283 Field
A3: v_pcb_dep_src_pf_ar_sa_dly | B3: rec_tp | C3: Record Type | H3: Account Number | J3: Completed | K3: 20 Doc
A4: v_pcb_dep_src_pf_ar_sa_dly | B4: acct_num | C4: Account Number | H4: Source Position Date
A5: v_pcb_dep_src_pf_ar_sa_dly | B5: src_pos_dt | C5: Source Position Date | H5: Account Name in Thai
A6: v_pcb_dep_src_pf_ar_sa_dly | B6: acct_nm_in_thai | C6: Account Name in Thai | H6: Account Name in English
A7: v_pcb_dep_src_pf_ar_sa_dly | B7: acct_nm_in_eng | C7: Account Name in English | H7: Account Open Date
A8: v_pcb_dep_src_pf_ar_sa_dly | B8: acct_open_dt | C8: Account Open Date | H8: Account Close Date
A9: v_pcb_dep_src_pf_ar_sa_dly | B9: acct_cls_dt | C9: Account Close Date | H9: Account Status Code
A10: v_pcb_dep_src_pf_ar_sa_dly | B10: acct_st_cd | C10: Account Status Code | H10: Customer Classification Type Code
A11: v_pcb_dep_src_pf_ar_sa_dly | B11: cst_cl_tp_cd | C11: Customer Classification Type Code | H11: Business Sector Code
A12: v_pcb_dep_src_pf_ar_sa_dly | B12: bsn_sect_cd | C12: Business Sector Code | H12: Branch Code
A13: v_pcb_dep_src_pf_ar_sa_dly | B13: br_cd | C13: Branch Code | H13: Currency Code
A14: v_pcb_dep_src_pf_ar_sa_dly | B14: ccy_cd | C14: Currency Code | H14: Outstanding Balance Amount
A15: v_pcb_dep_src_pf_ar_sa_dly | B15: otsnd_bal_amt | C15: Outstanding Balance Amount | H15: Open Balance Amount
... A42: v_pcb_dep_src_pf_ar_sa_dly | B42: hold_bal_amt | C42: Hold Balance Amount | H42: Change E-Saving Current Date
A43: v_pcb_dep_src_pf_ar_sa_dly | C43: Change E-Saving Current Date | H43: Change E-Saving Current Timestamp
A44: v_pcb_dep_src_pf_ar_sa_dly | C44: Change E-Saving Current Timestamp | H44: Change E-Saving Device Number
A45: v_pcb_dep_src_pf_ar_sa_dly | C45: Change E-Saving Device Number | H45: Change E-Saving Service Branch Code
A46: v_pcb_dep_src_pf_ar_sa_dly | C46: Change E-Saving Service Branch Code | H46: E-Saving Account Flag
A47: v_pcb_dep_src_pf_ar_sa_dly | C47: E-Saving Account Flag | H47: Profile Interest Deposit Number
A48: v_pcb_dep_src_pf_ar_sa_dly | B48: prfl_int_dep_num | C48: Profile Interest Deposit Number | H48: Accumulate Interest Paid Amount
A49: v_pcb_dep_src_pf_ar_sa_dly | B49: accum_int_paid_amt | C49: Accumulate Interest Paid Amount | H49: Previous Year Interest Paid Amount
A50: v_pcb_dep_src_pf_ar_sa_dly | B50: pyr_int_paid_amt | C50: Previous Year Interest Paid Amount | H50: Year-To-Date Interest Paid Amount
A51: v_pcb_dep_src_pf_ar_sa_dly | B51: yr_to_dt_int_paid_amt | C51: Year-To-Date Interest Paid Amount | H51: Backup Withholding Flag
A52: v_pcb_dep_src_pf_ar_sa_dly | C52: Backup Withholding Flag | H52: Previous Year Backup Withholding Paid Amount
A53: v_pcb_dep_src_pf_ar_sa_dly | C53: Previous Year Backup Withholding Paid Amount | H53: Year-To-Date Backup Withholding Paid Amount
A54: v_pcb_dep_src_pf_ar_sa_dly | C54: Year-To-Date Backup Withholding Paid Amount | H54: Tax Owner Customer Identification Number
A55: v_pcb_dep_src_pf_ar_sa_dly | B55: tax_ownr_cst_id_num | C55: Tax Owner Customer Identification Number | H55: Interest Withholding Calculation Method
A56: v_pcb_dep_src_pf_ar_sa_dly | B56: int_wthld_cal_mthd | C56: Interest Withholding Calculation Method | H56: Tax Key
A57: v_pcb_dep_src_pf_ar_sa_dly | B57: tax_key | C57: Tax Key | H57: Surety Account Flag
A58: v_pcb_dep_src_pf_ar_sa_dly | C58: Surety Account Flag | H58: Block Code
A59: v_pcb_dep_src_pf_ar_sa_dly | B59: block_cd | C59: Block Code | H59: Debit or Credit Allowable code
A60: v_pcb_dep_src_pf_ar_sa_dly | C60: Debit or Credit Allowable code | H60: Tax Identification Number
A61: v_pcb_dep_src_pf_ar_sa_dly | B61: tax_id_num | C61: Tax Identification Number | H61: customer identification number
A62: v_pcb_dep_src_pf_ar_sa_dly | B62: cst_id_num | C62: customer identification number | H62: Principal Amount
A63: v_pcb_dep_src_pf_ar_sa_dly | B63: load_tms | H63: Positive Interest Payment Frequency
A64: v_pcb_dep_src_pf_ar_sa_dly | B64: src_sys_id | H64: Positive Interest Payment Frequency Unit
A65: v_pcb_dep_src_pf_ar_sa_dly | B65: ptn_yyyy | H65: Negative Interest Payment Frequency
A66: v_pcb_dep_src_pf_ar_sa_dly | B66: ptn_mm | H66: Negative Interest Payment Frequency Unit
...

Sheet Batch2lot1
A1: View Name | B1: Column Name | C1: Column Name | E1: Description | F1: Mandatory | G1: Data Type | H1: Data Size | I1: Confidential Data | J1: Transformation Rules | K1: T Seq. | L1: Table Name | M1: Column Name | Q1: Status
A2: v_pcb_loan_common_limit_info | B2: pos_dt | C2: pos_dt | F2: M | G2: date | H2: 8 | J2: Direct Move | K2: 1 | L2: pcb_loan_common_limit_info | M2: pos_dt | Q2: clmn_nm_blnk | R2: =_xlfn.CONCAT(COUNTBLANK(B2:B3469)," Field") -> 198 Field
A3: v_pcb_loan_common_limit_info | B3: rec_tp | D3: rec_tp | E3: Record Type | F3: M | G3: alphanumeric | H3: 1 | J3: Direct Move | K3: 2 | L3: pcb_loan_common_limit_info | M3: rec_type | Q3: Completed | R3: 19 Doc
A4: v_pcb_loan_common_limit_info | B4: lmt_acct_num | D4: lmt_acct_num | E4: Limit Account Number | F4: M | G4: string | H4: 19 | J4: Direct Move | K4: 3 | L4: pcb_loan_common_limit_info | M4: lmt_ac_ar_id
A5: v_pcb_loan_common_limit_info | B5: prfl_acct_num | D5: prfl_acct_num | E5: Profile Account Number | F5: M | G5: string | H5: 12 | J5: Direct Move | K5: 4 | L5: pcb_loan_common_limit_info | M5: prfl_ac_ar_id
A6: v_pcb_loan_common_limit_info | B6: root_commit_acct_num | D6: root_commit_acct_num | E6: Root Commitment Account Number | F6: M | G6: string | H6: 19 | J6: Direct Move | K6: 5 | L6: pcb_loan_common_limit_info | M6: root_ac_ar_id
A7: v_pcb_loan_common_limit_info | B7: lmt_nm_in_thai | D7: lmt_nm_in_thai | E7: Limit Name in Thai | F7: M | G7: string | H7: 180 | J7: Direct Move | K7: 6 | L7: pcb_loan_common_limit_info | M7: ar_nm_th
A8: v_pcb_loan_common_limit_info | B8: lmt_nm_in_eng | D8: lmt_nm_in_eng | E8: Limit Name in English | F8: O | G8: string | H8: 180 | J8: Direct Move | K8: 7 | L8: pcb_loan_common_limit_info | M8: ar_nm_eng
A9: v_pcb_loan_common_limit_info | B9: cst_tp_cd | D9: cst_tp_cd | E9: Customer Type Code | F9: M | G9: string | H9: 5 | J9: Direct Move | K9: 8 | L9: pcb_loan_common_limit_info | M9: cst_typ_id
A10: v_pcb_loan_common_limit_info | B10: kbnk_bsn_cd | D10: kbnk_bsn_cd | E10: Kbank Business Code | F10: O | G10: string | H10: 9 | J10: Direct Move | K10: 9 | L10: pcb_loan_common_limit_info | M10: bsn_code_id
A11: v_pcb_loan_common_limit_info | B11: acct_pps_tp_cd | D11: acct_pps_tp_cd | E11: Account Purpose Type Code | F11: O | G11: string | H11: 3 | J11: Direct Move | K11: 10 | L11: pcb_loan_common_limit_info | M11: loan_pps_typ_id
A12: v_pcb_loan_common_limit_info | B12: cntrct_dt | D12: cntrct_dt | E12: Contract Date | F12: M | G12: date | H12: 10 | J12: Direct Move | K12: 11 | L12: pcb_loan_common_limit_info | M12: ctr_dt
A13: v_pcb_loan_common_limit_info | B13: eff_dt | D13: eff_dt | E13: Effective Date | F13: M | G13: date | H13: 10 | J13: Direct Move | K13: 12 | L13: pcb_loan_common_limit_info | M13: eff_dt
A14: v_pcb_loan_common_limit_info | B14: mat_dt | D14: mat_dt | E14: Maturity Date | F14: M | G14: date | H14: 10 | J14: Direct Move | K14: 13 | L14: pcb_loan_common_limit_info | M14: lmt_end_dt
A15: v_pcb_loan_common_limit_info | B15: acct_st | D15: acct_st | E15: Account Status | F15: M | G15: string | H15: 1 | J15: Direct Move | K15: 14 | L15: pcb_loan_common_limit_info | M15: ac_sts_id
... A31: v_pcb_loan_common_limit_info | B31: use_lmt_amt | D31: use_lmt_amt | E31: Used Limit Amount | F31: M | G31: decimal | H31: 17 | J31: Direct Move | K31: 30 | L31: pcb_loan_common_limit_info | M31: used_lmt
A32: v_pcb_loan_common_limit_info | E32: ESR Amount | F32: M | G32: decimal | H32: 17 | J32: Direct Move | K32: 31 | L32: pcb_loan_common_limit_info | M32: esr
A33: v_pcb_loan_common_limit_info | B33: unuse_lmt_amt | D33: unuse_lmt_amt | E33: Unused Limit Amount | F33: M | G33: decimal | H33: 17 | J33: Direct Move | K33: 32 | L33: pcb_loan_common_limit_info | M33: unused_lmt
A34: v_pcb_loan_common_limit_info | B34: avl_lmt_amt | D34: avl_lmt_amt | E34: Available Limit Amount | F34: M | G34: decimal | H34: 17 | J34: Direct Move | K34: 33 | L34: pcb_loan_common_limit_info | M34: avl_lmt
A35: v_pcb_loan_common_limit_info | B35: hold_amt | D35: hold_amt | E35: Holding Amount | F35: O | G35: decimal | H35: 17 | J35: Direct Move | K35: 34 | L35: pcb_loan_common_limit_info | M35: hold_amt
A36: v_pcb_loan_common_limit_info | B36: li_idv_f | D36: li_idv_f | E36: LI Individual Flag | F36: M | G36: smallint | H36: 1 | J36: Direct Move | K36: 35 | L36: pcb_loan_common_limit_info | M36: li_idv_flg
A37: v_pcb_loan_common_limit_info | E37: CIS Number | F37: M | G37: bigint | H37: 10 | J37: Direct Move | K37: 36 | L37: pcb_loan_common_limit_info | M37: cis_id
A38: v_pcb_loan_common_limit_info | B38: tot_li_amt | D38: tot_li_amt | E38: Total LI Amount | F38: O | G38: decimal | H38: 17 | J38: Direct Move | K38: 37 | L38: pcb_loan_common_limit_info | M38: tot_li_amt
A39: v_pcb_loan_common_limit_info | B39: tot_dr_amt | D39: tot_dr_amt | E39: Total Debit Amount | F39: O | G39: decimal | H39: 17 | J39: Direct Move | K39: 38 | L39: pcb_loan_common_limit_info | M39: tot_dr_amt
A40: v_pcb_loan_common_limit_info | B40: crrnt_int_rate_tp_cd | D40: crrnt_int_rate_tp_cd | E40: Current Interest Rate Type Code | F40: O | G40: string | H40: 3 | J40: Direct Move | K40: 39 | L40: pcb_loan_common_limit_info | M40: eff_int_rate_typ_id
A41: v_pcb_loan_common_limit_info | B41: crrnt_sprd_int_rate_sign | D41: crrnt_sprd_int_rate_sign | E41: Current Spread Interest Rate Sign | F41: O | G41: string | H41: 1 | J41: Direct Move | K41: 40 | L41: pcb_loan_common_limit_info | M41: eff_sprd_int_sign
A42: v_pcb_loan_common_limit_info | B42: crrnt_sprd_int_rate_pct | D42: crrnt_sprd_int_rate_pct | E42: Current Spread Interest Rate Percentage | F42: O | G42: decimal | H42: 8 | J42: Direct Move | K42: 41 | L42: pcb_loan_common_limit_info | M42: eff_sprd_int_rate
A43: v_pcb_loan_common_limit_info | B43: max_day | D43: max_day | E43: Max Day | F43: O | G43: smallint | H43: 4 | J43: Direct Move | K43: 42 | L43: pcb_loan_common_limit_info | M43: max_days
A44: v_pcb_loan_common_limit_info | B44: dedct_acct_num | D44: dedct_acct_num | E44: Deduction Account Number | F44: O | G44: string | H44: 10 | J44: Direct Move | K44: 43 | L44: pcb_loan_common_limit_info | M44: refr_ddcn_ac
A45: v_pcb_loan_common_limit_info | B45: dep_acct_num | D45: dep_acct_num | E45: Deposit Account Number | F45: O | G45: string | H45: 10 | J45: Direct Move | K45: 44 | L45: pcb_loan_common_limit_info | M45: rel_ac_ar_id
A46: v_pcb_loan_common_limit_info | B46: dep_sub_acct_num | D46: dep_sub_acct_num | E46: Deposit Sub Account Number | F46: O | G46: string | H46: 3 | J46: Direct Move | K46: 45 | L46: pcb_loan_common_limit_info | M46: rel_ac_ar_id_sub
A47: v_pcb_loan_common_limit_info | B47: dep_acct_crrnt_sprd_rate_pct | D47: dep_acct_crrnt_sprd_rate_pct | E47: Deposit Account Current Spread Rate Percentage | F47: O | G47: decimal | H47: 8 | J47: Direct Move | K47: 46 | L47: pcb_loan_common_limit_info | M47: rel_ac_sign_sprd
A48: v_pcb_loan_common_limit_info | B48: cr_prgm_cd | D48: cr_prgm_cd | E48: Credit Program Code | F48: O | G48: string | H48: 40 | J48: Direct Move | K48: 47 | L48: pcb_loan_common_limit_info | M48: cr_prog
A49: v_pcb_loan_common_limit_info | B49: appl_id_num | D49: appl_id_num | E49: Application Identification Number | F49: O | G49: string | H49: 50 | J49: Direct Move | K49: 48 | L49: pcb_loan_common_limit_info | M49: kcps_app_id
... A51: v_pcb_loan_common_limit_info | B51: fillr | D51: fillr | E51: Filler | F51: O | G51: string | H51: 183 | J51: Direct Move | K51: 50 | L51: pcb_loan_common_limit_info | M51: filler
A52: v_pcb_loan_common_limit_info | B52: load_tms | C52: load_tms | F52: M | G52: timestamp | H52: 26 | J52: Direct Move | K52: 51 | L52: pcb_loan_common_limit_info | M52: load_tms
A53: v_pcb_loan_common_limit_info | B53: src_sys_id | C53: src_sys_id | F53: M | G53: string | H53: 10 | J53: Direct Move | K53: 52 | L53: pcb_loan_common_limit_info | M53: src_sys_id
A54: v_pcb_loan_common_limit_info | B54: ptn_yyyy | C54: ptn_yyyy | F54: M | G54: string | H54: 4 | J54: Direct Move | K54: 53 | L54: pcb_loan_common_limit_info | M54: ptn_yyyy
A55: v_pcb_loan_common_limit_info | B55: ptn_mm | C55: ptn_mm | F55: M | G55: string | H55: 2 | J55: Direct Move | K55: 54 | L55: pcb_loan_common_limit_info | M55: ptn_mm
A56: v_pcb_loan_common_limit_info | B56: ptn_dd | C56: ptn_dd | F56: M | G56: string | H56: 2 | J56: Direct Move | K56: 55 | L56: pcb_loan_common_limit_info | M56: ptn_dd
...

Sheet Batch2lot2
A1: View Name | B1: Column Name | C1: sys+Column Name+add filler | D1: Column | E1: Key | F1: Description | G1: Mandatory | H1: Data Type | I1: Data Size | J1: Confidential Data | K1: Transformation Rules | L1: T Seq. | M1: Table Name | N1: Column Name | R1: Status
A2: v_gts_kbgt_cont_outstanding | B2: pos_dt | C2: pos_dt | E2: =VLOOKUP(F2,[13]abbr_btch2lot2!A:B,2,FALSE) -> #N/A | G2: M | H2: date | I2: 8 | K2: Direct Move | L2: 1 | M2: gts_kbgt_cont_outstanding | N2: pos_dt | R2: clmn_nm_blnk | S2: =_xlfn.CONCAT(COUNTBLANK(C2:C3469)," Field") -> 585 Field
A3: v_gts_kbgt_cont_outstanding | C3: acct_num | D3: acct_num | E3: =VLOOKUP(F3,[13]abbr_btch2lot2!A:B,2,FALSE) -> 1 | F3: Account Number | G3: M | H3: string | I3: 15 | K3: Direct Move | L3: 2 | M3: gts_kbgt_cont_outstanding | N3: trade_ref | R3: Completed | S3: 5 Doc
A4: v_gts_kbgt_cont_outstanding | C4: mgrt_acct_num | D4: mgrt_acct_num | E4: =VLOOKUP(F4,[13]abbr_btch2lot2!A:B,2,FALSE) -> 2 | F4: Migrated Account Number | G4: O | H4: string | I4: 15 | K4: Direct Move | L4: 3 | M4: gts_kbgt_cont_outstanding | N4: old_traderef
A5: v_gts_kbgt_cont_outstanding | E5: =VLOOKUP(F5,[13]abbr_btch2lot2!A:B,2,FALSE) -> 3 | F5: CIS Number | G5: M | H5: string | I5: 10 | K5: Direct Move | L5: 4 | M5: gts_kbgt_cont_outstanding | N5: cis_id
A6: v_gts_kbgt_cont_outstanding | C6: fclty_cd | D6: fclty_cd | E6: =VLOOKUP(F6,[13]abbr_btch2lot2!A:B,2,FALSE) -> 4 | F6: Facility Code | G6: O | H6: string | I6: 11 | K6: Direct Move | L6: 5 | M6: gts_kbgt_cont_outstanding | N6: facility_id
A7: v_gts_kbgt_cont_outstanding | C7: lmt_cd | D7: lmt_cd | E7: =VLOOKUP(F7,[13]abbr_btch2lot2!A:B,2,FALSE) -> 5 | F7: Limit Code | G7: O | H7: string | I7: 19 | K7: Direct Move | L7: 6 | M7: gts_kbgt_cont_outstanding | N7: limit_id
A8: v_gts_kbgt_cont_outstanding | C8: fclty_lvl | D8: fclty_lvl | E8: =VLOOKUP(F8,[13]abbr_btch2lot2!A:B,2,FALSE) -> 6 | F8: Facility Level | G8: O | H8: string | I8: 1 | K8: Direct Move | L8: 7 | M8: gts_kbgt_cont_outstanding | N8: facility_level
A9: v_gts_kbgt_cont_outstanding | C9: lvl_6_lmt_cd | D9: lvl_6_lmt_cd | E9: =VLOOKUP(F9,[13]abbr_btch2lot2!A:B,2,FALSE) -> 7 | F9: Level 6 Limit Code | G9: O | H9: string | I9: 19 | K9: Direct Move | L9: 8 | M9: gts_kbgt_cont_outstanding | N9: l6_limit_id
A10: v_gts_kbgt_cont_outstanding | C10: issu_dt | D10: issu_dt | E10: =VLOOKUP(F10,[13]abbr_btch2lot2!A:B,2,FALSE) -> 8 | F10: Issue Date | G10: M | H10: date | I10: 10 | K10: Direct Move | L10: 9 | M10: gts_kbgt_cont_outstanding | N10: issue_date
A11: v_gts_kbgt_cont_outstanding | C11: eff_dt | D11: eff_dt | E11: =VLOOKUP(F11,[13]abbr_btch2lot2!A:B,2,FALSE) -> 9 | F11: Effective Date | G11: M | H11: date | I11: 10 | K11: Direct Move | L11: 10 | M11: gts_kbgt_cont_outstanding | N11: eff_date
A12: v_gts_kbgt_cont_outstanding | C12: mat_dt | D12: mat_dt | E12: =VLOOKUP(F12,[13]abbr_btch2lot2!A:B,2,FALSE) -> 10 | F12: Maturity Date | G12: M | H12: date | I12: 10 | K12: Direct Move | L12: 11 | M12: gts_kbgt_cont_outstanding | N12: maturity-date
A13: v_gts_kbgt_cont_outstanding | C13: due_dt | D13: due_dt | E13: =VLOOKUP(F13,[13]abbr_btch2lot2!A:B,2,FALSE) -> 11 | F13: Due Date | G13: M | H13: date | I13: 10 | K13: Direct Move | L13: 12 | M13: gts_kbgt_cont_outstanding | N13: due-date
A14: v_gts_kbgt_cont_outstanding | C14: cls_dt | D14: cls_dt | E14: =VLOOKUP(F14,[13]abbr_btch2lot2!A:B,2,FALSE) -> 12 | F14: Close Date | G14: O | H14: date | I14: 10 | K14: Direct Move | L14: 13 | M14: gts_kbgt_cont_outstanding | N14: close_date
A15: v_gts_kbgt_cont_outstanding | C15: acct_st | D15: acct_st | E15: =VLOOKUP(F15,[13]abbr_btch2lot2!A:B,2,FALSE) -> 13 | F15: Account Status | G15: O | H15: string | I15: 1 | K15: Direct Move | L15: 14 | M15: gts_kbgt_cont_outstanding | N15: status
A16: v_gts_kbgt_cont_outstanding | C16: tenor | D16: tenor | E16: =VLOOKUP(F16,[13]abbr_btch2lot2!A:B,2,FALSE) -> 14 | F16: Tenor | G16: M | H16: decimal | I16: 5,0 | K16: Direct Move | L16: 15 | M16: gts_kbgt_cont_outstanding | N16: term
A17: v_gts_kbgt_cont_outstanding | C17: tenor_unit | D17: tenor_unit | E17: =VLOOKUP(F17,[13]abbr_btch2lot2!A:B,2,FALSE) -> 15 | F17: Tenor Unit | G17: M | H17: string | I17: 1 | K17: Direct Move | L17: 16 | M17: gts_kbgt_cont_outstanding | N17: term_unit
A18: v_gts_kbgt_cont_outstanding | C18: ccy_cd | D18: ccy_cd | E18: =VLOOKUP(F18,[13]abbr_btch2lot2!A:B,2,FALSE) -> 16 | F18: Currency Code | G18: M | H18: string | I18: 3 | K18: Direct Move | L18: 17 | M18: gts_kbgt_cont_outstanding | N18: ccy_code
A19: v_gts_kbgt_cont_outstanding | C19: orig_pnp_amt_in_orig_ccy | D19: orig_pnp_amt_in_orig_ccy | E19: =VLOOKUP(F19,[13]abbr_btch2lot2!A:B,2,FALSE) -> 17 | F19: Original Principal Amount in Original Currency | G19: M | H19: decimal | I19: 18,2 | K19: Direct Move | L19: 18 | M19: gts_kbgt_cont_outstanding | N19: prin_org_amount_ccy
A20: v_gts_kbgt_cont_outstanding | C20: orig_pnp_amt_in_thb | D20: orig_pnp_amt_in_thb | E20: =VLOOKUP(F20,[13]abbr_btch2lot2!A:B,2,FALSE) -> 18 | F20: Original Principal Amount in Thai Baht | G20: M | H20: decimal | I20: 18,2 | K20: Direct Move | L20: 19 | M20: gts_kbgt_cont_outstanding | N20: prin_org_amount_thb
A21: v_gts_kbgt_cont_outstanding | C21: crrnt_orig_pnp_amt_in_orig_ccy | D21: crrnt_orig_pnp_amt_in_orig_ccy | E21: =VLOOKUP(F21,[13]abbr_btch2lot2!A:B,2,FALSE) -> 19 | F21: Current Original Principal Amount in Original Currency | G21: M | H21: decimal | I21: 18,2 | K21: Direct Move | L21: 20 | M21: gts_kbgt_cont_outstanding | N21: prin_cur_amount_ccy
A22: v_gts_kbgt_cont_outstanding | C22: crrnt_orig_pnp_amt_in_thb | D22: crrnt_orig_pnp_amt_in_thb | E22: =VLOOKUP(F22,[13]abbr_btch2lot2!A:B,2,FALSE) -> 20 | F22: Current Original Principal Amount in Thai Baht | G22: M | H22: decimal | I22: 18,2 | K22: Direct Move | L22: 21 | M22: gts_kbgt_cont_outstanding | N22: prin_cur_amount_thb
A23: v_gts_kbgt_cont_outstanding | C23: dly_acru_int_amt_in_orig_ccy | D23: dly_acru_int_amt_in_orig_ccy | E23: =VLOOKUP(F23,[13]abbr_btch2lot2!A:B,2,FALSE) -> 21 | F23: Daily Accrued Interest amount in Original Currency | G23: M | H23: decimal | I23: 18,2 | K23: Direct Move | L23: 22 | M23: gts_kbgt_cont_outstanding | N23: int_daily_accru_ccy
A24: v_gts_kbgt_cont_outstanding | C24: dly_acru_int_amt_in_thb | D24: dly_acru_int_amt_in_thb | E24: =VLOOKUP(F24,[13]abbr_btch2lot2!A:B,2,FALSE) -> 22 | F24: Daily Accrued Interest amount in Thai Baht | G24: M | H24: decimal | I24: 18,2 | K24: Direct Move | L24: 23 | M24: gts_kbgt_cont_outstanding | N24: int_daily_accru_thb
A25: v_gts_kbgt_cont_outstanding | C25: rmain_acru_int_in_orig_ccy | D25: rmain_acru_int_in_orig_ccy | E25: =VLOOKUP(F25,[13]abbr_btch2lot2!A:B,2,FALSE) -> 23 | F25: Remain Accrued Interest in Original Currency | G25: M | H25: decimal | I25: 18,2 | K25: Direct Move | L25: 24 | M25: gts_kbgt_cont_outstanding | N25: int_remain_amount_ccy
A26: v_gts_kbgt_cont_outstanding | C26: rmain_acru_int_in_thb | D26: rmain_acru_int_in_thb | E26: =VLOOKUP(F26,[13]abbr_btch2lot2!A:B,2,FALSE) -> 24 | F26: Remain Accrued Interest in Thai Baht | G26: M | H26: decimal | I26: 18,2 | K26: Direct Move | L26: 25 | M26: gts_kbgt_cont_outstanding | N26: int_remain_amount_thb
A27: v_gts_kbgt_cont_outstanding | C27: discnt_amt_in_orig_ccy | D27: discnt_amt_in_orig_ccy | E27: =VLOOKUP(F27,[13]abbr_btch2lot2!A:B,2,FALSE) -> 25 | F27: Discount Amount in Original Currency | G27: O | H27: decimal | I27: 18,2 | K27: Direct Move | L27: 26 | M27: gts_kbgt_cont_outstanding | N27: disc_amount_ccy
A28: v_gts_kbgt_cont_outstanding | C28: discnt_amt_in_thb | D28: discnt_amt_in_thb | E28: =VLOOKUP(F28,[13]abbr_btch2lot2!A:B,2,FALSE) -> 26 | F28: Discount Amount in Thai Baht | G28: O | H28: decimal | I28: 18,2 | K28: Direct Move | L28: 27 | M28: gts_kbgt_cont_outstanding | N28: disc_amount_thb
A29: v_gts_kbgt_cont_outstanding | C29: amtz_amt_in_orig_ccy | D29: amtz_amt_in_orig_ccy | E29: =VLOOKUP(F29,[13]abbr_btch2lot2!A:B,2,FALSE) -> 27 | F29: Amortized amount in Original Currency | G29: O | H29: decimal | I29: 18,2 | K29: Direct Move | L29: 28 | M29: gts_kbgt_cont_outstanding | N29: amrz_amount_ccy
A30: v_gts_kbgt_cont_outstanding | C30: amtz_amt_in_thb | D30: amtz_amt_in_thb | E30: =VLOOKUP(F30,[13]abbr_btch2lot2!A:B,2,FALSE) -> 28 | F30: Amortized amount in Thai Baht | G30: O | H30: decimal | I30: 18,2 | K30: Direct Move | L30: 29 | M30: gts_kbgt_cont_outstanding | N30: amrz_amount_thb
... A41: v_gts_kbgt_cont_outstanding | C41: tot_unpaid_fee_amt_in_thb | D41: tot_unpaid_fee_amt_in_thb | E41: =VLOOKUP(F41,[13]abbr_btch2lot2!A:B,2,FALSE) -> 39 | F41: Total Unpaid Fee amount in Thai Baht | G41: M | H41: decimal | I41: 18,2 | K41: Direct Move | L41: 40 | M41: gts_kbgt_cont_outstanding | N41: unpaid_fee_thb
A42: v_gts_kbgt_cont_outstanding | C42: last_paymt_dt | D42: last_paymt_dt | E42: =VLOOKUP(F42,[13]abbr_btch2lot2!A:B,2,FALSE) -> 40 | F42: Last Payment Date | G42: O | H42: date | I42: 10 | K42: Direct Move | L42: 41 | M42: gts_kbgt_cont_outstanding | N42: date_of_last_payment
A43: v_gts_kbgt_cont_outstanding | C43: last_paymt_amt_in_orig_ccy | D43: last_paymt_amt_in_orig_ccy | E43: =VLOOKUP(F43,[13]abbr_btch2lot2!A:B,2,FALSE) -> 41 | F43: Last Payment Amount in Original Currency | G43: O | H43: decimal | I43: 18,2 | K43: Direct Move | L43: 42 | M43: gts_kbgt_cont_outstanding | N43: amt_last_payment_ccy
A44: v_gts_kbgt_cont_outstanding | C44: last_paymt_amt_in_thb | D44: last_paymt_amt_in_thb | E44: =VLOOKUP(F44,[13]abbr_btch2lot2!A:B,2,FALSE) -> 42 | F44: Last Payment Amount in Thai Baht | G44: O | H44: decimal | I44: 18,2 | K44: Direct Move | L44: 43 | M44: gts_kbgt_cont_outstanding | N44: amt_last_payment_thb
A45: v_gts_kbgt_cont_outstanding | C45: accum_paymt_amt_in_orig_ccy | D45: accum_paymt_amt_in_orig_ccy | E45: =VLOOKUP(F45,[13]abbr_btch2lot2!A:B,2,FALSE) -> 43 | F45: Accumulate Payment Amount in Original Currency | G45: O | H45: bigint | I45: 18 | K45: Direct Move | L45: 44 | M45: gts_kbgt_cont_outstanding | N45: amt_accum_payment_ccy
A46: v_gts_kbgt_cont_outstanding | C46: accum_paymt_amt_in_thb | D46: accum_paymt_amt_in_thb | E46: =VLOOKUP(F46,[13]abbr_btch2lot2!A:B,2,FALSE) -> 44 | F46: Accumulate Payment Amount in Thai Baht | G46: O | H46: bigint | I46: 18 | K46: Direct Move | L46: 45 | M46: gts_kbgt_cont_outstanding | N46: amt_accum_payment_thb
A47: v_gts_kbgt_cont_outstanding | C47: mid_rate | D47: mid_rate | E47: =VLOOKUP(F47,[13]abbr_btch2lot2!A:B,2,FALSE) -> 45 | F47: Mid Rate | G47: M | H47: decimal | I47: 11,7 | K47: Direct Move | L47: 46 | M47: gts_kbgt_cont_outstanding | N47: mid_rate
A48: v_gts_kbgt_cont_outstanding | C48: crrnt_int_rate | D48: crrnt_int_rate | E48: =VLOOKUP(F48,[13]abbr_btch2lot2!A:B,2,FALSE) -> 46 | F48: Current Interest Rate | G48: M | H48: decimal | I48: 9,7 | K48: Direct Move | L48: 47 | M48: gts_kbgt_cont_outstanding | N48: eff_rate
A49: v_gts_kbgt_cont_outstanding | C49: rate_tp_cd | D49: rate_tp_cd | E49: =VLOOKUP(F49,[13]abbr_btch2lot2!A:B,2,FALSE) -> 47 | F49: Rate Type Code | G49: M | H49: string | I49: 3 | K49: Direct Move | L49: 48 | M49: gts_kbgt_cont_outstanding | N49: rate_type
A50: v_gts_kbgt_cont_outstanding | C50: sign | D50: sign | E50: =VLOOKUP(F50,[13]abbr_btch2lot2!A:B,2,FALSE) -> 48 | F50: Sign | G50: O | H50: string | I50: 1 | K50: Direct Move | L50: 49 | M50: gts_kbgt_cont_outstanding | N50: sign
...

Sheet Batch 1
A1: =COUNTA(A3:A949) -> 37
A2: No | B2: Batch | C2: System | D2: File name/Table name | E2: EBAN/DIH | F2: KBMF File Reference | G2: CBR EBAN File Reference | H2: Status
A3: 1 | B3: Batch 1 | C3: PCB-Deposit | D3: src_pf_ar_sa_dly_yyyymmdd.txt | E3: EBAN
A4: 2 | B4: Batch 1 | C4: PCB-Deposit | D4: src_pf_ar_ca_dly_yyyymmdd.txt | E4: EBAN
A5: 3 | B5: Batch 1 | C5: PCB-Deposit | D5: src_pf_ar_fx_dly_yyyymmdd.txt | E5: EBAN
A6: 4 | B6: Batch 1 | C6: PCB-Deposit | D6: src_pf_ar_sf_dly_yyyymmdd.txt | E6: EBAN
A7: 5 | B7: Batch 1 | C7: PCB-Deposit | D7: PCB_DIH_ExtRATE1_YYYYMMDD.txt | E7: EBAN
A8: 6 | B8: Batch 1 | C8: PCB-Deposit | D8: Common_Market_Code.txt | E8: EBAN
A9: 7 | B9: Batch 1 | C9: PCB-Lending | D9: Common_Account_Info_YYYYMMDD.txt | E9: EBAN
A10: 8 | B10: Batch 1 | C10: PCB-Lending | D10: Common_Limit_Info_YYYYMMDD.txt | E10: EBAN
A11: 9 | B11: Batch 1 | C11: PCB-Lending | D11: Account_Defer_Interest_YYYYMMDD.txt | E11: EBAN
A12: 10 | B12: Batch 1 | C12: PCB-Lending | D12: Common_Rate_Type.txt | E12: EBAN
A13: 11 | B13: Batch 1 | C13: PCB-Lending | D13: Common_Billing_Detail_yyyymmdd.txt | E13: EBAN
A14: 12 | B14: Batch 1 | C14: PCB-Lending | D14: Common_Billing_yyyymmdd.txt | E14: EBAN
... A39: 37 | B39: Batch 1 | C39: PCB-Lending | D39: Bene_Product_Type_YYYYMMDD.txt | E39: EBAN

Sheet Batch 2 - Old
A1: 404
A2: No | B2: Batch | C2: System | D2: Plan | E2: File name/Table name | F2: EBAN/DIH | G2: KBMF File Reference | H2: CBR File Reference | I2: Status
A3: 1 | B3: Batch 2 | C3: K PLUS | D3: Plan B | E3: View_JMobileActLog_Log | F3: EBAN | H3: CBR_V_MB_ACTN_LOG_v.1.8
A4: 2 | B4: Batch 2 | C4: K PLUS | D4: Plan B | E4: View_JMobile_Log | F4: EBAN | H4: CBR_V_MB_PLUS_IP_MSTR_V.0.13
A5: 3 | B5: Batch 2 | C5: K PLUS | D5: Plan B | E5: View_JMobileAcctCard_Log | F5: EBAN | H5: CBR_V_MB_PLUS_IP_X_AR_REL_v0.5
A6: 4 | B6: Batch 2 | C6: LPM-AS/400​ | D6: Plan B | E6: LMD23400 | F6: EBAN | H6: CBR_VP_LPM_LMT_AR_INF_BFR_WRTOF_v0.5
A7: 5 | B7: Batch 2 | C7: LPM-AS/400​ | D7: Plan B | E7: L01D070 | F7: EBAN | H7: CBR_V_LPM_AR_WRTOF_RCV_v0.9.xlsx
A8: 6 | B8: Batch 2 | C8: LPM-AS/400​ | D8: Plan B | E8: L01W769 | F8: EBAN | H8: CBR_VP_LPM_LN_CNTG_DMMY_CLSS_PRVN_v0.19
A9: 7 | B9: Batch 2 | C9: LPM-AS/400​ | D9: Plan B | E9: L01W181 | F9: EBAN | H9: CBR_VP_LPM_LN_CARD_CLSS_PRVN_v0.18
A10: 8 | B10: Batch 2 | C10: LPM-AS/400​ | D10: Plan B | E10: L01W909 | F10: EBAN | H10: CBR_VP_LPM_LN_CNTG_CLSS_PRVN_v0.18
A11: 9 | B11: Batch 2 | C11: LPM-AS/400​ | D11: Plan B | E11: L01D027 | F11: EBAN | H11: CBR_VP_LPM_AR_CLSS_QLY_v.0.8
A12: 10 | B12: Batch 2 | C12: LPM-AS/400​ | D12: Plan B | E12: L01D003 | F12: EBAN | H12: CBR_VP_LPM_AR_INF_v0.14
A13: 11 | B13: Batch 2 | C13: LPM-AS/400​ | D13: Plan B | E13: LMD24000 | F13: EBAN | H13: CBR_VP_LPM_LMT_AR_INF_v0.11
A14: 12 | B14: Batch 2 | C14: LPM-AS/400​ | D14: Plan B | E14: DRD07200-HIST-TDR-ACCT-FILE | F14: EBAN | H14: CBR_VP_LPM_AR_TDR_TRCK
... A45: 43 | B45: Batch 2 | C45: LPM-TDR | D45: Plan B | E45: CT1D408A_YYYYMMDD.txt | F45: EBAN | H45: CBR_VP_TDR_AR_RESHD_v1.1
A46: 44 | B46: Batch 2 | C46: Trade-Navigator | D46: Plan B | E46: RDT_SCF_CL_ACCT_NAL_yyyymmdd.txt | F46: EBAN
A47: 45 | B47: Batch 2 | C47: Trade-Navigator | D47: Plan B | E47: LCR070_YYYYMMDD.txt | F47: EBAN
A48: 46 | B48: Batch 2 | C48: Trade-Navigator | D48: Plan B | E48: SRC_EXIMAR_YYYYMMDD.TXT | F48: EBAN
A49: 47 | B49: Batch 2 | C49: Trade-Navigator | D49: Plan B | E49: BASEL_YYYYMMDD.txt | F49: EBAN
A50: 48 | B50: Batch 2 | C50: Trade-Navigator | D50: Plan B | E50: EB059F_YYYYMMDD.TXT | F50: EBAN
A51: 49 | B51: Batch 2 | C51: Trade-Navigator | D51: Plan B | E51: AML_YYYYMMDD.txt | F51: EBAN
A52: 50 | B52: Batch 2 | C52: Trade-Navigator | D52: Plan B | E52: LPM030_YYYYMMDD.TXT | F52: EBAN
A53: 51 | B53: Batch 2 | C53: Trade-Navigator | D53: Plan B | E53: src_trdna_txn_trd_fnc_yyyymmdd.txt | F53: EBAN
A54: 52 | B54: Batch 2 | C54: Trade-Navigator | D54: Plan B | E54: LAP040F_YYYYMM.txt | F54: EBAN
A55: 53 | B55: Batch 2 | C55: Trade-Navigator | D55: Plan B | E55: CT1D364_yyyymm.txt | F55: EBAN
A56: 54 | B56: Batch 2 | C56: Trade-Navigator | D56: Plan B | E56: LCR071_YYYYMMDD.txt | F56: EBAN
A57: 55 | B57: Batch 2 | C57: Trade-Navigator | D57: Plan B | E57: daily_turn_over_yyyymmdd.txt | F57: EBAN
... A184: 182 | B184: Batch 2 | C184: UD | D184: Plan B | E184: VW_TRANSACTIONEXT | F184: EBAN
A185: 183 | B185: Batch 2 | C185: CIS | D185: Plan A | E185: MQ_AR_IPXAR
A186: 184 | B186: Batch 2 | C186: CIS | D186: Plan A | E186: MQ_DIH_ARXCONTACT
A187: 185 | B187: Batch 2 | C187: CIS | D187: Plan A | E187: V_RELAR
A188: 186 | B188: Batch 2 | C188: CIS | D188: Plan A | E188: MQ_ARXAR
A189: 187 | B189: Batch 2 | C189: CIS | D189: Plan A | E189: V_CNTCHNNL
A190: 188 | B190: Batch 2 | C190: CIS | D190: Plan A | E190: V_CNTPDDMN
A191: 189 | B191: Batch 2 | C191: CIS | D191: Plan A | E191: V_CNTPURPS
A192: 190 | B192: Batch 2 | C192: CIS | D192: Plan A | E192: MQ_DNTCNT
A193: 191 | B193: Batch 2 | C193: CIS | D193: Plan A | E193: V_DOCTP
A194: 192 | B194: Batch 2 | C194: CIS | D194: Plan A | E194: V_IPMERGE
A195: 193 | B195: Batch 2 | C195: CIS | D195: Plan A | E195: MQ_DIH_OTHDOC
A196: 194 | B196: Batch 2 | C196: CIS | D196: Plan A | E196: V_CNTRELTP
...

Sheet Source Inventory
M1: …/inbound/source_file/mdp/<Source System>/<env>/<file name> | O1: abfss://inbound@stmdpsea<env>in001.dfs.core.windows.net/<database> / <table> / <partitions>​
A2: # | B2: Business Area | C2: source system name | D2: System Name | E2: Abbr src_sys | F2: src_sys_id | G2: Source Status | H2: KBMF Approach | I2: Action | J2: Plan | K2: Case | L2: Remark | M2: Target Folder on Landing Zone VM | N2: path on cloud | O2: adls on cloud
A3: 1 | B3: Deposit | C3: Profile Core Banking - Deposit | D3: PCB-Deposit | E3: pcb_dep | F3: 668 | G3: Group 1 | H3: EBAN | I3: Fon to follow up | J3: Plan B | K3: Source operation to extract file to EBAN landing zone | M3: ="/datasource/inbound/source_file/mdp/"&E3&"/" -> /datasource/inbound/source_file/mdp/pcb_dep/ | N3: ="/inbound/source_file/mdp/"&E3&"/" -> /inbound/source_file/mdp/pcb_dep/ | O3: ="abfss://inbound@stmdpsea<env>in001.dfs.core.windows.net/source_file/mdp/"&E3&"/" -> abfss://inbound@stmdpsea<env>in001.dfs.core.windows.net/source_file/mdp/pcb_dep/
A4: 2 | B4: Credit | C4: Profile Core Banking - Lending | D4: PCB-Lending | E4: pcb_loan | F4: 668.08 | G4: Group 1 | H4: EBAN | I4: Fon to follow up | J4: Plan B | K4: Source operation to extract file to EBAN landing zone | M4: ="/datasource/inbound/source_file/mdp/"&E4&"/" -> /datasource/inbound/source_file/mdp/pcb_loan/ | N4: ="/inbound/source_file/mdp/"&E4&"/" -> /inbound/source_file/mdp/pcb_loan/ | O4: ="abfss://inbound@stmdpsea<env>in001.dfs.core.windows.net/source_file/mdp/"&E4&"/" -> abfss://inbound@stmdpsea<env>in001.dfs.core.windows.net/source_file/mdp/pcb_loan/
A5: 3 | B5: LPM | C5: LPM ON AS/400 | D5: LPM-AS/400​ | E5: lpm_as400 | F5: 75 | G5: Group 1 | H5: EBAN | I5: Fon to follow up | J5: Plan B | K5: Direct Access | L5: Case 3: KBMF from Source this Friday | M5: ="/datasource/inbound/source_file/mdp/"&E5&"/" -> /datasource/inbound/source_file/mdp/lpm_as400/ | N5: ="/inbound/source_file/mdp/"&E5&"/" -> /inbound/source_file/mdp/lpm_as400/ | O5: ="abfss://inbound@stmdpsea<env>in001.dfs.core.windows.net/source_file/mdp/"&E5&"/" -> abfss://inbound@stmdpsea<env>in001.dfs.core.windows.net/source_file/mdp/lpm_as400/
A6: 4 | B6: FCD | C6: Foreign Currency Profile - FCD | D6: FCD | E6: fcd | F6: 640 | G6: Group 1 | H6: EBAN | I6: Fon to follow up | J6: Plan B | K6: Source operation to extract file to EBAN landing zone | M6: ="/datasource/inbound/source_file/mdp/"&E6&"/" -> /datasource/inbound/source_file/mdp/fcd/ | N6: ="/inbound/source_file/mdp/"&E6&"/" -> /inbound/source_file/mdp/fcd/ | O6: ="abfss://inbound@stmdpsea<env>in001.dfs.core.windows.net/source_file/mdp/"&E6&"/" -> abfss://inbound@stmdpsea<env>in001.dfs.core.windows.net/source_file/mdp/fcd/
A7: 5 | B7: Customer Demographic | C7: Customer Information System | D7: CIS | E7: cis | F7: 176 | G7: Group 2.1 | H7: Source | I7: Received existing KBMF (22-Dec:14) Pending new KBMF | J7: Plan A | M7: ="/datasource/inbound/source_file/mdp/"&E7&"/" -> /datasource/inbound/source_file/mdp/cis/ | N7: ="/inbound/source_file/mdp/"&E7&"/" -> /inbound/source_file/mdp/cis/ | O7: ="abfss://inbound@stmdpsea<env>in001.dfs.core.windows.net/source_file/mdp/"&E7&"/" -> abfss://inbound@stmdpsea<env>in001.dfs.core.windows.net/source_file/mdp/cis/
A8: 6 | B8: Customer Consent | C8: Consent Management System | D8: CSM | E8: csm | F8: 780 | G8: Group 2.2 | H8: Source | I8: Received existing KBMF (22-Dec:17) Pending new KBMF | J8: Plan A | L8: pending ~2 files | M8: ="/datasource/inbound/source_file/mdp/"&E8&"/" -> /datasource/inbound/source_file/mdp/csm/ | N8: ="/inbound/source_file/mdp/"&E8&"/" -> /inbound/source_file/mdp/csm/ | O8: ="abfss://inbound@stmdpsea<env>in001.dfs.core.windows.net/source_file/mdp/"&E8&"/" -> abfss://inbound@stmdpsea<env>in001.dfs.core.windows.net/source_file/mdp/csm/
A9: 7 | B9: KPLUS | C9: KPLUS | D9: K PLUS | E9: kplus | F9: 509 | G9: Group 2.3 | H9: EBAN | I9: Fon to follow up | J9: Plan B | K9: Direct Access | L9: Case 3: KBMF from Source | M9: ="/datasource/inbound/source_file/mdp/"&E9&"/" -> /datasource/inbound/source_file/mdp/kplus/ | N9: ="/inbound/source_file/mdp/"&E9&"/" -> /inbound/source_file/mdp/kplus/ | O9: ="abfss://inbound@stmdpsea<env>in001.dfs.core.windows.net/source_file/mdp/"&E9&"/" -> abfss://inbound@stmdpsea<env>in001.dfs.core.windows.net/source_file/mdp/kplus/
A10: 8 | B10: Trade | C10: Trade Finance - Trade Navigator | D10: Trade-Navigator | E10: trade_na | F10: 451 | G10: Group 2.3 | H10: EBAN | I10: Fon to follow up | J10: Plan B | K10: Source operation to extract file to EBAN landing zone | M10: ="/datasource/inbound/source_file/mdp/"&E10&"/" -> /datasource/inbound/source_file/mdp/trade_na/ | N10: ="/inbound/source_file/mdp/"&E10&"/" -> /inbound/source_file/mdp/trade_na/ | O10: ="abfss://inbound@stmdpsea<env>in001.dfs.core.windows.net/source_file/mdp/"&E10&"/" -> abfss://inbound@stmdpsea<env>in001.dfs.core.windows.net/source_file/mdp/trade_na/
A11: 9 | B11: Trade | C11: New-Trade | D11: New-Trade | E11: gts | F11: 735 | G11: Group 2.3 | H11: EBAN | I11: Fon to follow up | J11: Plan B | K11: Source operation to extract file to EBAN landing zone | M11: ="/datasource/inbound/source_file/mdp/"&E11&"/" -> /datasource/inbound/source_file/mdp/gts/ | N11: ="/inbound/source_file/mdp/"&E11&"/" -> /inbound/source_file/mdp/gts/ | O11: ="abfss://inbound@stmdpsea<env>in001.dfs.core.windows.net/source_file/mdp/"&E11&"/" -> abfss://inbound@stmdpsea<env>in001.dfs.core.windows.net/source_file/mdp/gts/
A12: 10 | B12: Supply Chain | C12: Supply Chain | D12: Supply Chain | E12: scf | F12: 460 | G12: Group 2.3 | H12: EBAN/DIH | I12: Fon to follow up | J12: Plan B | K12: - Direct Access '- Source operation to extract file to EBAN landing zone | L12: pending ~2 files Case 3: KBMF from Source | M12: ="/datasource/inbound/source_file/mdp/"&E12&"/" -> /datasource/inbound/source_file/mdp/scf/ | N12: ="/inbound/source_file/mdp/"&E12&"/" -> /inbound/source_file/mdp/scf/ | O12: ="abfss://inbound@stmdpsea<env>in001.dfs.core.windows.net/source_file/mdp/"&E12&"/" -> abfss://inbound@stmdpsea<env>in001.dfs.core.windows.net/source_file/mdp/scf/
A13: 11 | B13: Factoring | C13: Factoring | D13: Factoring | E13: dgtl_fctrng | F13: 754 | G13: Group 2.3 | H13: EBAN | I13: Fon to follow up | J13: Plan B | K13: - Direct Access - Source operation to extract file to EBAN landing zone | L13: TBC - Timezone and charset Case 2: File - KBMF From EBAN Case 3: View - KBMF From Source | M13: ="/datasource/inbound/source_file/mdp/"&E13&"/" -> /datasource/inbound/source_file/mdp/dgtl_fctrng/ | N13: ="/inbound/source_file/mdp/"&E13&"/" -> /inbound/source_file/mdp/dgtl_fctrng/ | O13: ="abfss://inbound@stmdpsea<env>in001.dfs.core.windows.net/source_file/mdp/"&E13&"/" -> abfss://inbound@stmdpsea<env>in001.dfs.core.windows.net/source_file/mdp/dgtl_fctrng/
A14: 12 | B14: MM/ REPO | C14: Murex | D14: Murex | E14: mx | F14: 590 | G14: Group 2.3 | H14: EBAN | I14: Fon to follow up | J14: Plan B | K14: Source operation to extract file to EBAN landing zone | M14: ="/datasource/inbound/source_file/mdp/"&E14&"/" -> /datasource/inbound/source_file/mdp/mx/ | N14: ="/inbound/source_file/mdp/"&E14&"/" -> /inbound/source_file/mdp/mx/ | O14: ="abfss://inbound@stmdpsea<env>in001.dfs.core.windows.net/source_file/mdp/"&E14&"/" -> abfss://inbound@stmdpsea<env>in001.dfs.core.windows.net/source_file/mdp/mx/
A15: 13 | B15: Fund | C15: Unit Dealing | D15: UD | E15: ud | F15: 607 | G15: Group 2.3 | H15: EBAN/DIH | I15: Fon to follow up | J15: Plan B | K15: - Direct Access - Source operation to extract file to EBAN landing zone | L15: Case 2: File - KBMF From EBAN Case 3: View - KBMF From Source | M15: ="/datasource/inbound/source_file/mdp/"&E15&"/" -> /datasource/inbound/source_file/mdp/ud/ | N15: ="/inbound/source_file/mdp/"&E15&"/" -> /inbound/source_file/mdp/ud/ | O15: ="abfss://inbound@stmdpsea<env>in001.dfs.core.windows.net/source_file/mdp/"&E15&"/" -> abfss://inbound@stmdpsea<env>in001.dfs.core.windows.net/source_file/mdp/ud/
A16: 14 | B16: Fund | D16: KS | E16: ks | F16: KS | G16: Group 2.3 | H16: EBAN/DIH | I16: Fon to follow up | J16: Plan B | M16: ="/datasource/inbound/source_file/mdp/"&E16&"/" -> /datasource/inbound/source_file/mdp/ks/ | N16: ="/inbound/source_file/mdp/"&E16&"/" -> /inbound/source_file/mdp/ks/ | O16: ="abfss://inbound@stmdpsea<env>in001.dfs.core.windows.net/source_file/mdp/"&E16&"/" -> abfss://inbound@stmdpsea<env>in001.dfs.core.windows.net/source_file/mdp/ks/
A17: 15 | B17: Master of Code Description | C17: Reference Data Management | D17: RDM | E17: rdm | F17: 655 | G17: Group 2.3 | H17: EBAN/DIH | I17: Fon to follow up | J17: Plan A | L17: Changed to Plan A Both control file and tailor | M17: ="/datasource/inbound/source_file/mdp/dih/" -> /datasource/inbound/source_file/mdp/dih/ | N17: ="/inbound/source_file/mdp/dih/" -> /inbound/source_file/mdp/dih/ | O17: ="abfss://inbound@stmdpsea<env>in001.dfs.core.windows.net/source_file/mdp/dih/" -> abfss://inbound@stmdpsea<env>in001.dfs.core.windows.net/source_file/mdp/dih/
A18: 16 | B18: Write off for Lending | C18: LPM-WriteOff | D18: LPM-WriteOff | E18: lpm_wrtoff | F18: 235 | G18: Group 1 | H18: EBAN | I18: Fon to follow up | J18: Plan B | K18: Source operation to extract file to EBAN landing zone | M18: ="/datasource/inbound/source_file/mdp/"&E18&"/" -> /datasource/inbound/source_file/mdp/lpm_wrtoff/ | N18: ="/inbound/source_file/mdp/"&E18&"/" -> /inbound/source_file/mdp/lpm_wrtoff/ | O18: ="abfss://inbound@stmdpsea<env>in001.dfs.core.windows.net/source_file/mdp/"&E18&"/" -> abfss://inbound@stmdpsea<env>in001.dfs.core.windows.net/source_file/mdp/lpm_wrtoff/
A19: 17 | B19: Legal status for Lending​ | C19: LEC - BAD BANK | D19: LEC​ | E19: lec | F19: 72 | G19: Group 1 | H19: EBAN | I19: Fon to follow up | J19: Plan B | K19: Source operation to extract file to EBAN landing zone | M19: ="/datasource/inbound/source_file/mdp/"&E19&"/" -> /datasource/inbound/source_file/mdp/lec/ | N19: ="/inbound/source_file/mdp/"&E19&"/" -> /inbound/source_file/mdp/lec/ | O19: ="abfss://inbound@stmdpsea<env>in001.dfs.core.windows.net/source_file/mdp/"&E19&"/" -> abfss://inbound@stmdpsea<env>in001.dfs.core.windows.net/source_file/mdp/lec/
A20: 18 | B20: CC/ XPC | C20: CardLink | D20: Cardlink | E20: cardlink | F20: 268 | G20: Group 1.2 | H20: Source | I20: Received existing KBMF (22-Dec:8) Pending new KBMF | J20: Plan A | L20: MQ, Not provide control file | M20: ="/datasource/inbound/source_file/mdp/"&E20&"/" -> /datasource/inbound/source_file/mdp/cardlink/ | N20: ="/inbound/source_file/mdp/"&E20&"/" -> /inbound/source_file/mdp/cardlink/ | O20: ="abfss://inbound@stmdpsea<env>in001.dfs.core.windows.net/source_file/mdp/"&E20&"/" -> abfss://inbound@stmdpsea<env>in001.dfs.core.windows.net/source_file/mdp/cardlink/
A21: 19 | B21: Debit Card​ | C21: CardLink (TPN) | D21: Cardlink(TPN​) | E21: cardlink_acq | F21: 268.01 | G21: Group 1.2 | H21: Source | I21: Name helps to follow up | J21: Plan A | L21: Not provide control file | M21: ="/datasource/inbound/source_file/mdp/"&E21&"/" -> /datasource/inbound/source_file/mdp/cardlink_acq/ | N21: ="/inbound/source_file/mdp/"&E21&"/" -> /inbound/source_file/mdp/cardlink_acq/ | O21: ="abfss://inbound@stmdpsea<env>in001.dfs.core.windows.net/source_file/mdp/"&E21&"/" -> abfss://inbound@stmdpsea<env>in001.dfs.core.windows.net/source_file/mdp/cardlink_acq/
A22: 20 | B22: Customer RM Segment | C22: Sales Smart | D22: RMST | E22: rmst | F22: 723 | G22: Group 2.2 | H22: Source | I22: Name helps to follow up | J22: Plan A | L22: Sales Smart will sent KBMF by 12-Jan (As agreed in WS) | M22: ="/datasource/inbound/source_file/mdp/"&E22&"/" -> /datasource/inbound/source_file/mdp/rmst/ | N22: ="/inbound/source_file/mdp/"&E22&"/" -> /inbound/source_file/mdp/rmst/ | O22: ="abfss://inbound@stmdpsea<env>in001.dfs.core.windows.net/source_file/mdp/"&E22&"/" -> abfss://inbound@stmdpsea<env>in001.dfs.core.windows.net/source_file/mdp/rmst/
A23: 21 | B23: Debit Card​ | C23: Centralized Card Management System | D23: CCMS​ | E23: ccms | F23: 772 | G23: Group 2.2 | H23: Source | I23: Name helps to follow up | J23: Plan A | M23: ="/datasource/inbound/source_file/mdp/"&E23&"/" -> /datasource/inbound/source_file/mdp/ccms/ | N23: ="/inbound/source_file/mdp/"&E23&"/" -> /inbound/source_file/mdp/ccms/ | O23: ="abfss://inbound@stmdpsea<env>in001.dfs.core.windows.net/source_file/mdp/"&E23&"/" -> abfss://inbound@stmdpsea<env>in001.dfs.core.windows.net/source_file/mdp/ccms/
A24: 22 | B24: Exchange Rate​ | C24: FX at booth | D24: FXBOOTH​ | E24: fxb | F24: 745 | G24: Group 2.3 | I24: Fon to follow up | J24: Plan B | L24: ผ่านทาง DIH | M24: ="/datasource/inbound/source_file/mdp/"&E24&"/" -> /datasource/inbound/source_file/mdp/fxb/ | N24: ="/inbound/source_file/mdp/"&E24&"/" -> /inbound/source_file/mdp/fxb/ | O24: ="abfss://inbound@stmdpsea<env>in001.dfs.core.windows.net/source_file/mdp/"&E24&"/" -> abfss://inbound@stmdpsea<env>in001.dfs.core.windows.net/source_file/mdp/fxb/
A25: 23 | C25: HRMIS-Centralized RC | D25: HRCRC | E25: hrcrc | F25: 497 | M25: ="/datasource/inbound/source_file/mdp/"&E25&"/" -> /datasource/inbound/source_file/mdp/hrcrc/ | N25: ="/inbound/source_file/mdp/"&E25&"/" -> /inbound/source_file/mdp/hrcrc/ | O25: ="abfss://inbound@stmdpsea<env>in001.dfs.core.windows.net/source_file/mdp/"&E25&"/" -> abfss://inbound@stmdpsea<env>in001.dfs.core.windows.net/source_file/mdp/hrcrc/
A26: 24 | B26: KBANK VS KBANK-Group | C26: HRIS | D26: HRIS | E26: hris | F26: 506 | M26: ="/datasource/inbound/source_file/mdp/"&E26&"/" -> /datasource/inbound/source_file/mdp/hris/ | N26: ="/inbound/source_file/mdp/"&E26&"/" -> /inbound/source_file/mdp/hris/ | O26: ="abfss://inbound@stmdpsea<env>in001.dfs.core.windows.net/source_file/mdp/"&E26&"/" -> abfss://inbound@stmdpsea<env>in001.dfs.core.windows.net/source_file/mdp/hris/

Sheet Technical Source Inventory
A1: 0 | B1: 0 | C1: 0 | D1: 0 | E1: 0 | F1: 0 | G1: 0 | H1: 0 | I1: 0 | J1: 0 | K1: 0 | L1: 0 | M1: 0 | N1: 0 | O1: 0
A2: # | B2: Business Area | C2: source system name | D2: Abbr src_sys | E2: System Name | F2: Count Summary | G2: Source Status | H2: KBMF Approach | I2: Action | J2: Note for Baseline 1 | K2: Plan | L2: Extraction Cases | M2: Case | N2: Remark | O2: KBMF Status | P2: Workshop Status | Q2: Access status | R2: Integration Status | S2: Pending Action | T2: Plan | U2: FW Extraction Case | V2: File Type | W2: Control File Type | X2: Environments | Y2: Database Type | Z2: Authentication | AA2: Availability | AB2: Timezone | AC2: Charset | AD2: Extraction Method | AE2: Extraction Size | AF2: Extraction Size Limit | AG2: Encryption | AH2: Parallel Extraction
A3: 1 | B3: Deposit | C3: Profile Core Banking - Deposit | D3: PCB_DEP | E3: PCB-Deposit | F3: 5 | G3: Group 1 | H3: EBAN | I3: Fon to follow up | J3: 45273 | K3: Plan B | L3: Push | M3: Source operation to extract file to EBAN landing zone | N3: 0 | O3: Received | P3: Pending | S3: Test extraction framework on DEV | T3: Plan B | U3: Pull File (EBAN LANDING)
A4: 2 | B4: Credit | C4: Profile Core Banking - Lending | D4: PCB_LOAN | E4: PCB-Lending | F4: 5 | G4: Group 1 | H4: EBAN | I4: Fon to follow up | J4: 45273 | K4: Plan B | L4: Push | M4: Source operation to extract file to EBAN landing zone | N4: 0 | O4: Received | P4: Pending | S4: Test extraction framework on DEV | T4: Plan B | U4: Pull File (EBAN LANDING)
A5: 3 | B5: LPM | C5: LPM ON AS/400 | D5: LPM_AS400 | E5: LPM-AS/400​ | F5: 7 | G5: Group 1 | H5: EBAN | I5: Fon to follow up | J5: 45280 | K5: Plan B | L5: Pull | M5: Direct Access | N5: Case 3: KBMF from Source this Friday | O5: In Progress | P5: Pending | S5: To get approval for pulling EBAN's DB | T5: Plan B | U5: Pull File (EBAN IN)
A6: 4 | B6: FCD | C6: Foreign Currency Profile - FCD | D6: FCD | E6: FCD | F6: 1 | G6: Group 1 | H6: EBAN | I6: Fon to follow up | J6: 45280 | K6: Plan B | L6: Push | M6: Source operation to extract file to EBAN landing zone | N6: 0 | O6: Received | P6: Pending | S6: Test extraction framework on DEV | T6: Plan B | U6: Pull File (EBAN LANDING)
A7: 5 | B7: Customer Demographic | C7: Customer Information System | D7: CIS | E7: CIS | F7: 16 | G7: Group 2.1 | H7: Source | I7: Received existing KBMF (22-Dec:14) Pending new KBMF | J7: 45280 | K7: Plan A | L7: Push | M7: 0 | N7: 0 | O7: In Progress | P7: Started | S7: ACN to confirm the on-prem VM's path | T7: Plan A | U7: Push File | V7: Text | W7: Control File | AD7: Initial - Full Dump On-going - Delta | AE7: 300M-600M records
A8: 6 | B8: Customer Consent | C8: Consent Management System | D8: CSM | E8: CSM | F8: 10 | G8: Group 2.2 | H8: Source | I8: Received existing KBMF (22-Dec:17) Pending new KBMF | J8: 45280 | K8: Plan A | L8: Push | M8: 0 | N8: pending ~2 files | O8: In Progress | P8: Started | S8: ACN to confirm the on-prem VM's path | T8: Plan A | U8: Push File | V8: Text | W8: Control File
A9: 7 | B9: KPLUS | C9: KPLUS | D9: KPLUS | E9: K PLUS | F9: 3 | G9: Group 2.3 | H9: EBAN | I9: Fon to follow up | J9: 45280 | K9: Plan B | L9: Pull | M9: Direct Access | N9: Case 3: KBMF from Source | O9: In Progress | P9: Pending | S9: Test extraction framework on DEV | T9: Plan B | U9: Pull File (EBAN LANDING)
A10: 8 | B10: Trade | C10: Trade Finance - Trade Navigator | D10: TRADE_NA | E10: Trade-Navigator | F10: 2 | G10: Group 2.3 | H10: EBAN | I10: Fon to follow up | J10: 45280 | K10: Plan B | L10: Push | M10: Source operation to extract file to EBAN landing zone | N10: 0 | O10: Received | P10: Pending | S10: Test extraction framework on DEV | T10: Plan B | U10: Pull File (EBAN LANDING)
A11: 9 | B11: Trade | C11: New-Trade | D11: GTS | E11: New-Trade | F11: 2 | G11: Group 2.3 | H11: EBAN | I11: Fon to follow up | J11: 45280 | K11: Plan B | L11: Push | M11: Source operation to extract file to EBAN landing zone | N11: 0 | O11: In Progress | P11: Pending | S11: Test extraction framework on DEV | T11: Plan B | U11: Pull File (EBAN LANDING)
A12: 10 | B12: Supply Chain | C12: Supply Chain | D12: SCF | E12: Supply Chain | F12: 6 | G12: Group 2.3 | H12: EBAN/DIH | I12: Fon to follow up | J12: 45280 | K12: Plan B | L12: Pull and Push | M12: - Direct Access '- Source operation to extract file to EBAN landing zone | N12: pending ~2 files Case 3: KBMF from Source | O12: Received | P12: Started | S12: To attend solution&architect session for source pulling confirmation | T12: Plan B | U12: Pull Database | X12: SIT/ UAT/ PRD | Y12: SQL Server 2016 | Z12: User/ Password - obtained | AA12: After 8:00 PM | AB12: UTC+7 | AC12: Pending | AF12: None | AG12: None | AH12: Available
A13: 11 | B13: Factoring | C13: Factoring | D13: DGTL_FCTRNG | E13: Factoring | F13: 2 | G13: Group 2.3 | H13: EBAN | I13: Fon to follow up | J13: 45280 | K13: Plan B | L13: Pull and Push | M13: - Direct Access - Source operation to extract file to EBAN landing zone | N13: TBC - Timezone and charset Case 2: File - KBMF From EBAN Case 3: View - KBMF From Source | O13: In Progress | P13: Started | S13: To request firewall and user/password for source DB access | T13: Plan B | U13: Pull Database | X13: DEV/ SIT/ UAT/ PRD | Y13: SQL Server 2016 | Z13: User/ Password | AA13: Pending | AB13: SE Asia Standard Time | AC13: Thai_CI_AS | AF13: None | AG13: Test - Masked Prod - None | AH13: Available
A14: 12 | E14: Factoring | S14: Test extraction framework on DEV | T14: Plan B | U14: Pull File (EBAN LANDING)
A15: 12 | B15: MM/ REPO | C15: Murex | D15: MX | E15: Murex | F15: 2 | G15: Group 2.3 | H15: EBAN | I15: Fon to follow up | J15: 45280 | K15: Plan B | L15: Push | M15: Source operation to extract file to EBAN landing zone | N15: 0 | O15: Received | P15: Pending | S15: Test extraction framework on DEV | T15: Plan B | U15: Pull File (EBAN LANDING)
A16: 13 | B16: KBANK VS KBANK-Group | C16: HRIS | D16: HRIS | E16: HRIS | F16: 1 | G16: Group 2.3 | H16: EBAN | I16: Fon to follow up | J16: 45280 | K16: Plan B | L16: Push | M16: Source operation to extract file to EBAN landing zone | N16: 0 | O16: Pending to provide | P16: Pending | S16: Test extraction framework on DEV | T16: Plan B | U16: Pull File (EBAN LANDING)
A17: 14 | D17: UD | E17: UD | S17: Test extraction framework on DEV | T17: Plan B | U17: Pull File (EBAN LANDING)
A18: 15 | B18: Fund | C18: Unit Dealing | D18: UD | E18: UD | F18: 8 | G18: Group 2.3 | H18: EBAN/DIH | I18: Fon to follow up | J18: 45280 | K18: Plan B | L18: Pull and Push | M18: - Direct Access - Source operation to extract file to EBAN landing zone | N18: Case 2: File - KBMF From EBAN Case 3: View - KBMF From Source | O18: Pending to provide | P18: Started | S18: To request firewall and user/password for source DB access | T18: Plan B | U18: Pull Database | X18: SIT/UAT (CTE2/3) not separated PRD | Y18: Oracle SQL 2011 | Z18: User/ Password | AA18: After 5:00 AM | AB18: UTC+7 | AC18: ASCII (UTF-8 might be available) | AF18: None | AG18: Test - Masked Prod - None | AH18: Not Available
A19: 16 | B19: Master of Code Description | C19: Reference Data Management | D19: RDM | E19: RDM | F19: 11 | G19: Group 2.3 | H19: EBAN/DIH | I19: Fon to follow up | J19: 45280 | K19: Plan A | L19: Push | M19: 0 | N19: Changed to Plan A Both control file and tailor | O19: In Progress | P19: Started | S19: ACN to confirm the on-prem VM's path | T19: Plan A | U19: Push File (DIH) | V19: Text | W19: Pending
A20: 17 | B20: Write off for Lending | C20: LPM-WriteOff | D20: LPM_WRTOFF | E20: LPM-WriteOff | F20: 1 | G20: Group 1 | H20: EBAN | I20: Fon to follow up | J20: 45287 | K20: Plan B | L20: Push | M20: Source operation to extract file to EBAN landing zone | N20: 0 | O20: Pending to provide | P20: Pending | S20: Test extraction framework on DEV | T20: Plan B | U20: Pull File (EBAN LANDING)
A21: 18 | B21: Legal status for Lending​ | C21: LEC - BAD BANK | D21: LEC | E21: LEC​ | F21: 1 | G21: Group 1 | H21: EBAN | I21: Fon to follow up | J21: 45287 | K21: Plan B | L21: Push | M21: Source operation to extract file to EBAN landing zone | N21: 0 | O21: Pending to provide | P21: Pending | S21: Test extraction framework on DEV | T21: Plan B | U21: Pull File (EBAN LANDING)
A22: 19 | B22: CC/ XPC | C22: CardLink | D22: CARDLINK | E22: Cardlink | F22: 11 | G22: Group 1.2 | H22: Source | I22: Received existing KBMF (22-Dec:8) Pending new KBMF | J22: 45287 | K22: Plan A | L22: Push | M22: 0 | N22: MQ, Not provide control file | O22: Pending to provide | P22: Started | S22: Workshop for MQ's topic subscription Friday 2024-01-19 *To discuss consuming from streaming hub | T22: Plan A | U22: Pull File | V22: (Cardlink JCB) Streaming - Kafka
A23: 20 | D23: CARDLINK | E23: Cardlink | S23: *Pending | T23: Plan B | U23: Pull EBAN File
A24: 21 | B24: Debit Card​ | C24: CardLink (TPN) | D24: CARDLINK_ACQ | E24: Cardlink(TPN​) | F24: 4 | G24: Group 1.2 | H24: Source | I24: Name helps to follow up | J24: 45287 | K24: Plan A | L24: Push | M24: 0 | N24: Not provide control file | O24: Pending to provide | P24: Started | S24: ACN to confirm the on-prem VM's path | T24: Plan A | U24: Pull File | V24: Mainframe
A25: 22 | B25: Customer RM Segment | C25: Sales Smart | D25: RMST | E25: RMST | F25: 1 | G25: Group 2.2 | H25: Source | I25: Name helps to follow up | J25: 45287 | K25: Plan A | L25: Push | M25: 0 | N25: Sales Smart will sent KBMF by 12-Jan (As agreed in WS) | O25: Pending to provide | P25: Started | S25: ACN to confirm the on-prem VM's path | T25: Plan A | U25: Push File
A26: 23 | B26: Debit Card​ | C26: Centralized Card Management System | D26: CCMS | E26: CCMS​ | F26: 4 | G26: Group 2.2 | H26: Source | I26: Name helps to follow up | J26: 45287 | K26: Plan A | L26: Push | M26: 0 | N26: 0 | O26: Pending to provide | P26: Started | S26: ACN to confirm the on-prem VM's path | T26: Plan A | U26: Push File | V26: Text | W26: Control File | AG26: Pending (inquiring if credit no. can be non-encrypted)
A27: 24 | B27: Exchange Rate​ | C27: FX at booth | D27: FXB | E27: FXBOOTH​ | F27: 1 | G27: Group 2.3 | H27: 0 | I27: Fon to follow up | J27: 45287 | K27: Plan B | L27: 0 | M27: 0 | N27: ผ่านทาง DIH | O27: Pending to provide | P27: Pending | T27: Plan A | U27: Push File (DIH)
A28: 25 | B28: 0 | C28: DIH | D28: DIH | E28: DIH | F28: 1 | G28: Group 2.3 | H28: 0 | I28: 0 | J28: 0 | K28: Plan A | L28: Push | M28: 0 | N28: 0 | O28: In Progress | P28: Pending | S28: DIH to discuss internally for file push | T28: Plan A | U28: Push File (DIH)
B30: Push Cases | C30: KBMF Received 15/21
B31: Pull Cases | C31: 3/6 | D31: *KPLUS on 2024-01-16
B32: Streaming Case | C32: 1 | D32: Cardlink
B33: Pull Databases | C33: SQL Server 2016
C34: Oracle SQL 2011 | D34: *To send user request for additional source push | Q34: Cardlink, DIH | S34: Request additional users | U34: IP, Port, user, path
Q36: DIH/RDM merged | R36: using mount disk | S36: K.Yui follow up on mount disk permissions | U36: *EBAN IT setting permissions
R37: 1 file pull from DIH
D40: Sending a list of sources to be pulled, to request for firewall
D41: Files | E41: Windows/ Linux | P41: IP/port/OS | Q41: AFT: Windows must include tectia
D43: EBAN sources: mount disk | P43: *Check for each source pulling from EBAN if its disk is mounted to the on-prem VM
P44: เช็คว่าหยิบจากเครื่อง ETL รึเปล่า -> อาจจะไม่ได้อยู่ใน mount disk | U44: sync who to provide credential (EBAN/DIH)
D46: Pull DB | P46: IP, port, credentials | Q46: Titsanu to send credentials to K.Yui/K.Jay

Sheet Dev detail plan
Y1: Start SIT | AT1: Start UAT
D2: Jan | N2: Feb | AQ2: Mar
A3: Tasks | B3: Team | C3: Remark | D3: 22 | E3: 23 | F3: 24 | G3: 25 | H3: 26 | I3: 27 | J3: 28 | K3: 29 | L3: 30 | M3: 31 | N3: 1 | O3: 2 | P3: 3 | Q3: 4 | R3: 5 | S3: 6 | T3: 7 | U3: 8 | V3: 9 | W3: 10 | X3: 11 | Y3: 12 | Z3: 13 | AA3: 14 | AB3: 15 | AC3: 16 | AD3: 17 | AE3: 18 | AF3: 19 | AG3: 20 | AH3: 21 | AI3: 22 | AJ3: 23 | AK3: 24 | AL3: 25 | AM3: 26 | AN3: 27 | AO3: 28 | AP3: 29 | AQ3: 1 | AR3: 2 | AS3: 3 | AT3: 4 | AU3: 5 | AV3: 6 | AW3: 7 | AX3: 8 | AY3: 9 | AZ3: 10 | BA3: 11 | BB3: 12 | BC3: 13 | BD3: 14 | BE3: 15 | BF3: 16 | BG3: 17 | BH3: 18 | BI3: 19 | BJ3: 20 | BK3: 21 | BL3: 22 | BM3: 23 | BN3: 24 | BO3: 25 | BP3: 26 | BQ3: 27 | BR3: 28 | BS3: 29 | BT3: 30 | BU3: 31
A4: Pull data from Linux file system
A5: solution on protocol | B5: fw | C5: Request session EBAN for existing approach | G5: x | H5: x | K5: x
A6: development | B6: fw | C6: Mock up system on cloud | K6: x | L6: x | M6: x
A7: unit test | B7: fw | N7: x | O7: x
A8: Integration | B8: kbtg/infra | R8: x | S8: x | T8: x | U8: x | V8: x
A9: SIT | Z9: x | AA9: x | AB9: x
A10: UAT
A11: Pull data from EBAN
A12: solution on protocol | C12: Request session EBAN for existing approach | G12: x | H12: x | K12: x
A13: development | M13: x | N13: x | O13: x
A14: unit test | R14: x | S14: x
A15: Integration | B15: kbtg/infra | T15: x | U15: x | V15: x
A16: SIT | Z16: x | AA16: x | AB16: x | AC16: x | AD16: x
A17: UAT
A18: Pull data from SQL DB
A19: solution on protocol | C19: Request session EBAN for existing approach | L19: x | M19: x
A20: development | N20: x | O20: x | R20: x
A21: unit test | S21: x | T21: x
A22: Integration | B22: kbtg/infra | U22: x | V22: x | Z22: x | AA22: x
A23: SIT
A24: UAT
A25: Pull data from Oracle
A26: solution on protocol | C26: Request session EBAN for existing approach | N26: x | O26: x
A27: development | R27: x | S27: x | T27: x
A28: unit test | U28: x | V28: x
